<?xml version="1.0" encoding="UTF-8"?>
<sdf version='1.10'>
  <model name='teTra_mk-7_EM2'>
    <pose>0 0 0.55 0 0 0</pose>
    <self_collide>false</self_collide>
    <static>false</static>

    <link name='base_link'>
      <pose>0 0 0 0 0 0</pose>
      <inertial>
        <pose>0.0000742623 0 -0.144690636 0 0 0</pose>
        <mass>1349.945</mass>
        <inertia>
          <ixx>4516.938144</ixx>
          <ixy>0</ixy>
          <ixz>-66.060588</ixz>
          <iyy>4576.816571</iyy>
          <iyz>0</iyz>
          <izz>8752.997733</izz>
        </inertia>
      </inertial>
      <collision name='fuselage_collision'>
        <pose>0 0 0 0 0 0</pose>
        <geometry>
          <box>
            <size>4.8 0.5 0.45</size>
          </box>
        </geometry>
        <surface>
          <contact>
            <ode>
              <kp>100000</kp>
              <kd>1.0</kd>
              <max_vel>0.1</max_vel>
              <min_depth>0.001</min_depth>
            </ode>
          </contact>
          <friction>
            <ode />
          </friction>
        </surface>
      </collision>
      <visual name='fuselage_visual'>
        <pose>0 0 0 0 0 0</pose>
        <geometry>
          <box>
            <size>4.8 0.5 0.45</size>
          </box>
        </geometry>
        <material>
          <ambient>0.17 0.18 0.20 1</ambient>
          <diffuse>0.17 0.18 0.20 1</diffuse>
        </material>
      </visual>
      <visual name='main_wing_visual'>
        <pose>0.35 0 0.16 0 0 0</pose>
        <geometry>
          <box>
            <size>2.5 8.6 0.10</size>
          </box>
        </geometry>
        <material>
          <ambient>0.24 0.27 0.29 1</ambient>
          <diffuse>0.24 0.27 0.29 1</diffuse>
        </material>
      </visual>
      <visual name='tail_boom_visual'>
        <pose>-2.7 0 0.1 0 0 0</pose>
        <geometry>
          <box>
            <size>2.6 0.18 0.18</size>
          </box>
        </geometry>
        <material>
          <ambient>0.14 0.15 0.16 1</ambient>
          <diffuse>0.14 0.15 0.16 1</diffuse>
        </material>
      </visual>
      <visual name='horizontal_tail_visual'>
        <pose>-3.55 0 0.2 0 0 0</pose>
        <geometry>
          <box>
            <size>0.85 2.7 0.08</size>
          </box>
        </geometry>
        <material>
          <ambient>0.24 0.27 0.29 1</ambient>
          <diffuse>0.24 0.27 0.29 1</diffuse>
        </material>
      </visual>
      <visual name='left_motor_beam_inner'>
        <pose>0 1.45 0.88 0 0 0</pose>
        <geometry>
          <box>
            <size>8.3 0.16 0.16</size>
          </box>
        </geometry>
        <material>
          <ambient>0.09 0.09 0.10 1</ambient>
          <diffuse>0.09 0.09 0.10 1</diffuse>
        </material>
      </visual>
      <visual name='right_motor_beam_inner'>
        <pose>0 -1.45 0.88 0 0 0</pose>
        <geometry>
          <box>
            <size>8.3 0.16 0.16</size>
          </box>
        </geometry>
        <material>
          <ambient>0.09 0.09 0.10 1</ambient>
          <diffuse>0.09 0.09 0.10 1</diffuse>
        </material>
      </visual>
      <visual name='left_motor_beam_outer'>
        <pose>0 4.0 0.88 0 0 0</pose>
        <geometry>
          <box>
            <size>4.1 0.14 0.14</size>
          </box>
        </geometry>
        <material>
          <ambient>0.09 0.09 0.10 1</ambient>
          <diffuse>0.09 0.09 0.10 1</diffuse>
        </material>
      </visual>
      <visual name='right_motor_beam_outer'>
        <pose>0 -4.0 0.88 0 0 0</pose>
        <geometry>
          <box>
            <size>4.1 0.14 0.14</size>
          </box>
        </geometry>
        <material>
          <ambient>0.09 0.09 0.10 1</ambient>
          <diffuse>0.09 0.09 0.10 1</diffuse>
        </material>
      </visual>
      <visual name='front_cross_beam'>
        <pose>2.0 0 0.88 0 0 0</pose>
        <geometry>
          <box>
            <size>0.16 8.1 0.16</size>
          </box>
        </geometry>
        <material>
          <ambient>0.09 0.09 0.10 1</ambient>
          <diffuse>0.09 0.09 0.10 1</diffuse>
        </material>
      </visual>
      <visual name='rear_cross_beam'>
        <pose>-2.0 0 0.88 0 0 0</pose>
        <geometry>
          <box>
            <size>0.16 8.1 0.16</size>
          </box>
        </geometry>
        <material>
          <ambient>0.09 0.09 0.10 1</ambient>
          <diffuse>0.09 0.09 0.10 1</diffuse>
        </material>
      </visual>
      <gravity>1</gravity>
      <velocity_decay />
      <self_collide>0</self_collide>

      <sensor name="imu_sensor" type="imu">
        <gz_frame_id>base_link</gz_frame_id>
        <always_on>1</always_on>
        <update_rate>250</update_rate>
        <imu>
          <angular_velocity>
            <x>
              <noise type="gaussian">
                <mean>0</mean>
                <stddev>0.0003394</stddev>
                <dynamic_bias_stddev>3.8785e-05</dynamic_bias_stddev>
                <dynamic_bias_correlation_time>1000</dynamic_bias_correlation_time>
              </noise>
            </x>
            <y>
              <noise type="gaussian">
                <mean>0</mean>
                <stddev>0.0003394</stddev>
                <dynamic_bias_stddev>3.8785e-05</dynamic_bias_stddev>
                <dynamic_bias_correlation_time>1000</dynamic_bias_correlation_time>
              </noise>
            </y>
            <z>
              <noise type="gaussian">
                <mean>0</mean>
                <stddev>0.0003394</stddev>
                <dynamic_bias_stddev>3.8785e-05</dynamic_bias_stddev>
                <dynamic_bias_correlation_time>1000</dynamic_bias_correlation_time>
              </noise>
            </z>
          </angular_velocity>
          <linear_acceleration>
            <x>
              <noise type="gaussian">
                <mean>0</mean>
                <stddev>0.004</stddev>
                <dynamic_bias_stddev>0.006</dynamic_bias_stddev>
                <dynamic_bias_correlation_time>300</dynamic_bias_correlation_time>
              </noise>
            </x>
            <y>
              <noise type="gaussian">
                <mean>0</mean>
                <stddev>0.004</stddev>
                <dynamic_bias_stddev>0.006</dynamic_bias_stddev>
                <dynamic_bias_correlation_time>300</dynamic_bias_correlation_time>
              </noise>
            </y>
            <z>
              <noise type="gaussian">
                <mean>0</mean>
                <stddev>0.004</stddev>
                <dynamic_bias_stddev>0.006</dynamic_bias_stddev>
                <dynamic_bias_correlation_time>300</dynamic_bias_correlation_time>
              </noise>
            </z>
          </linear_acceleration>
        </imu>
      </sensor>
      <sensor name="air_pressure_sensor" type="air_pressure">
        <gz_frame_id>base_link</gz_frame_id>
        <always_on>1</always_on>
        <update_rate>50</update_rate>
        <air_pressure>
          <pressure>
            <noise type="gaussian">
              <mean>0</mean>
              <stddev>0.01</stddev>
            </noise>
          </pressure>
        </air_pressure>
      </sensor>
      <sensor name="magnetometer_sensor" type="magnetometer">
        <gz_frame_id>base_link</gz_frame_id>
        <always_on>1</always_on>
        <update_rate>100</update_rate>
        <magnetometer>
          <x>
            <noise type="gaussian">
              <stddev>0.0001</stddev>
            </noise>
          </x>
          <y>
            <noise type="gaussian">
              <stddev>0.0001</stddev>
            </noise>
          </y>
          <z>
            <noise type="gaussian">
              <stddev>0.0001</stddev>
            </noise>
          </z>
        </magnetometer>
      </sensor>
      <sensor name="navsat_sensor" type="navsat">
        <gz_frame_id>base_link</gz_frame_id>
        <always_on>1</always_on>
        <update_rate>30</update_rate>
      </sensor>
    </link>

    <!-- H4T130 motor (13.2 kg) + ESC (2.3 kg) masses. ESC position is assumed colocated with the motor. -->
    <link name='motor_esc_0'>
      <pose>4.03 1.45 0.93 0 0 0</pose>
      <inertial>
        <pose>0 0 0 0 0 0</pose>
        <mass>15.5</mass>
        <inertia>
          <ixx>0.07546</ixx>
          <ixy>0</ixy>
          <ixz>0</ixz>
          <iyy>0.08136</iyy>
          <iyz>0</iyz>
          <izz>0.12040</izz>
        </inertia>
      </inertial>
    </link>
    <joint name='motor_esc_0_joint' type='fixed'>
      <parent>base_link</parent>
      <child>motor_esc_0</child>
    </joint>

    <link name='motor_esc_1'>
      <pose>1.95 1.45 0.93 0 0 0</pose>
      <inertial>
        <pose>0 0 0 0 0 0</pose>
        <mass>15.5</mass>
        <inertia>
          <ixx>0.07546</ixx>
          <ixy>0</ixy>
          <ixz>0</ixz>
          <iyy>0.08136</iyy>
          <iyz>0</iyz>
          <izz>0.12040</izz>
        </inertia>
      </inertial>
    </link>
    <joint name='motor_esc_1_joint' type='fixed'>
      <parent>base_link</parent>
      <child>motor_esc_1</child>
    </joint>

    <link name='motor_esc_2'>
      <pose>1.95 4.00 0.93 0 0 0</pose>
      <inertial>
        <pose>0 0 0 0 0 0</pose>
        <mass>15.5</mass>
        <inertia>
          <ixx>0.07546</ixx>
          <ixy>0</ixy>
          <ixz>0</ixz>
          <iyy>0.08136</iyy>
          <iyz>0</iyz>
          <izz>0.12040</izz>
        </inertia>
      </inertial>
    </link>
    <joint name='motor_esc_2_joint' type='fixed'>
      <parent>base_link</parent>
      <child>motor_esc_2</child>
    </joint>

    <link name='motor_esc_3'>
      <pose>-1.95 4.00 0.93 0 0 0</pose>
      <inertial>
        <pose>0 0 0 0 0 0</pose>
        <mass>15.5</mass>
        <inertia>
          <ixx>0.07546</ixx>
          <ixy>0</ixy>
          <ixz>0</ixz>
          <iyy>0.08136</iyy>
          <iyz>0</iyz>
          <izz>0.12040</izz>
        </inertia>
      </inertial>
    </link>
    <joint name='motor_esc_3_joint' type='fixed'>
      <parent>base_link</parent>
      <child>motor_esc_3</child>
    </joint>

    <link name='motor_esc_4'>
      <pose>-1.95 1.45 0.93 0 0 0</pose>
      <inertial>
        <pose>0 0 0 0 0 0</pose>
        <mass>15.5</mass>
        <inertia>
          <ixx>0.07546</ixx>
          <ixy>0</ixy>
          <ixz>0</ixz>
          <iyy>0.08136</iyy>
          <iyz>0</iyz>
          <izz>0.12040</izz>
        </inertia>
      </inertial>
    </link>
    <joint name='motor_esc_4_joint' type='fixed'>
      <parent>base_link</parent>
      <child>motor_esc_4</child>
    </joint>

    <link name='motor_esc_5'>
      <pose>-4.03 1.45 0.93 0 0 0</pose>
      <inertial>
        <pose>0 0 0 0 0 0</pose>
        <mass>15.5</mass>
        <inertia>
          <ixx>0.07546</ixx>
          <ixy>0</ixy>
          <ixz>0</ixz>
          <iyy>0.08136</iyy>
          <iyz>0</iyz>
          <izz>0.12040</izz>
        </inertia>
      </inertial>
    </link>
    <joint name='motor_esc_5_joint' type='fixed'>
      <parent>base_link</parent>
      <child>motor_esc_5</child>
    </joint>

    <link name='motor_esc_6'>
      <pose>-4.03 -1.45 0.93 0 0 0</pose>
      <inertial>
        <pose>0 0 0 0 0 0</pose>
        <mass>15.5</mass>
        <inertia>
          <ixx>0.07546</ixx>
          <ixy>0</ixy>
          <ixz>0</ixz>
          <iyy>0.08136</iyy>
          <iyz>0</iyz>
          <izz>0.12040</izz>
        </inertia>
      </inertial>
    </link>
    <joint name='motor_esc_6_joint' type='fixed'>
      <parent>base_link</parent>
      <child>motor_esc_6</child>
    </joint>

    <link name='motor_esc_7'>
      <pose>-1.95 -1.45 0.93 0 0 0</pose>
      <inertial>
        <pose>0 0 0 0 0 0</pose>
        <mass>15.5</mass>
        <inertia>
          <ixx>0.07546</ixx>
          <ixy>0</ixy>
          <ixz>0</ixz>
          <iyy>0.08136</iyy>
          <iyz>0</iyz>
          <izz>0.12040</izz>
        </inertia>
      </inertial>
    </link>
    <joint name='motor_esc_7_joint' type='fixed'>
      <parent>base_link</parent>
      <child>motor_esc_7</child>
    </joint>

    <link name='motor_esc_8'>
      <pose>-1.95 -4.00 0.93 0 0 0</pose>
      <inertial>
        <pose>0 0 0 0 0 0</pose>
        <mass>15.5</mass>
        <inertia>
          <ixx>0.07546</ixx>
          <ixy>0</ixy>
          <ixz>0</ixz>
          <iyy>0.08136</iyy>
          <iyz>0</iyz>
          <izz>0.12040</izz>
        </inertia>
      </inertial>
    </link>
    <joint name='motor_esc_8_joint' type='fixed'>
      <parent>base_link</parent>
      <child>motor_esc_8</child>
    </joint>

    <link name='motor_esc_9'>
      <pose>1.95 -4.00 0.93 0 0 0</pose>
      <inertial>
        <pose>0 0 0 0 0 0</pose>
        <mass>15.5</mass>
        <inertia>
          <ixx>0.07546</ixx>
          <ixy>0</ixy>
          <ixz>0</ixz>
          <iyy>0.08136</iyy>
          <iyz>0</iyz>
          <izz>0.12040</izz>
        </inertia>
      </inertial>
    </link>
    <joint name='motor_esc_9_joint' type='fixed'>
      <parent>base_link</parent>
      <child>motor_esc_9</child>
    </joint>

    <link name='motor_esc_10'>
      <pose>1.95 -1.45 0.93 0 0 0</pose>
      <inertial>
        <pose>0 0 0 0 0 0</pose>
        <mass>15.5</mass>
        <inertia>
          <ixx>0.07546</ixx>
          <ixy>0</ixy>
          <ixz>0</ixz>
          <iyy>0.08136</iyy>
          <iyz>0</iyz>
          <izz>0.12040</izz>
        </inertia>
      </inertial>
    </link>
    <joint name='motor_esc_10_joint' type='fixed'>
      <parent>base_link</parent>
      <child>motor_esc_10</child>
    </joint>

    <link name='motor_esc_11'>
      <pose>4.03 -1.45 0.93 0 0 0</pose>
      <inertial>
        <pose>0 0 0 0 0 0</pose>
        <mass>15.5</mass>
        <inertia>
          <ixx>0.07546</ixx>
          <ixy>0</ixy>
          <ixz>0</ixz>
          <iyy>0.08136</iyy>
          <iyz>0</iyz>
          <izz>0.12040</izz>
        </inertia>
      </inertial>
    </link>
    <joint name='motor_esc_11_joint' type='fixed'>
      <parent>base_link</parent>
      <child>motor_esc_11</child>
    </joint>
    <link name='rotor_0'>
      <pose>4.03 1.45 0.93 0 0 0</pose>
      <inertial><mass>2.0</mass><inertia><ixx>0.49075</ixx><ixy>0</ixy><ixz>0</ixz><iyy>0.49075</iyy><iyz>0</iyz><izz>0.98129</izz></inertia></inertial>
      <collision name='rotor_0_collision'><geometry><cylinder><length>0.025</length><radius>0.9906</radius></cylinder></geometry></collision>
      <visual name='rotor_0_visual'><geometry><cylinder><length>0.025</length><radius>0.9906</radius></cylinder></geometry><material><ambient>0.95 0.38 0.12 0.85</ambient><diffuse>0.95 0.38 0.12 0.85</diffuse></material></visual>
      <gravity>1</gravity><velocity_decay /><self_collide>0</self_collide>
    </link>
    <joint name='rotor_0_joint' type='revolute'>
      <child>rotor_0</child><parent>base_link</parent>
      <axis><xyz expressed_in="__model__">0 0.1302 0.9915</xyz><limit><lower>-1e+16</lower><upper>1e+16</upper></limit><dynamics><spring_reference>0</spring_reference><spring_stiffness>0</spring_stiffness></dynamics></axis>
    </joint>

    <link name='rotor_1'>
      <pose>1.95 1.45 0.93 0 0 0</pose>
      <inertial><mass>2.0</mass><inertia><ixx>0.49075</ixx><ixy>0</ixy><ixz>0</ixz><iyy>0.49075</iyy><iyz>0</iyz><izz>0.98129</izz></inertia></inertial>
      <collision name='rotor_1_collision'><geometry><cylinder><length>0.025</length><radius>0.9906</radius></cylinder></geometry></collision>
      <visual name='rotor_1_visual'><geometry><cylinder><length>0.025</length><radius>0.9906</radius></cylinder></geometry><material><ambient>0.10 0.45 0.90 0.85</ambient><diffuse>0.10 0.45 0.90 0.85</diffuse></material></visual>
      <gravity>1</gravity><velocity_decay /><self_collide>0</self_collide>
    </link>
    <joint name='rotor_1_joint' type='revolute'>
      <child>rotor_1</child><parent>base_link</parent>
      <axis><xyz expressed_in="__model__">0 -0.1302 0.9915</xyz><limit><lower>-1e+16</lower><upper>1e+16</upper></limit><dynamics><spring_reference>0</spring_reference><spring_stiffness>0</spring_stiffness></dynamics></axis>
    </joint>

    <link name='rotor_2'>
      <pose>1.95 4.00 0.93 0 0 0</pose>
      <inertial><mass>2.0</mass><inertia><ixx>0.49075</ixx><ixy>0</ixy><ixz>0</ixz><iyy>0.49075</iyy><iyz>0</iyz><izz>0.98129</izz></inertia></inertial>
      <collision name='rotor_2_collision'><geometry><cylinder><length>0.025</length><radius>0.9906</radius></cylinder></geometry></collision>
      <visual name='rotor_2_visual'><geometry><cylinder><length>0.025</length><radius>0.9906</radius></cylinder></geometry><material><ambient>0.95 0.38 0.12 0.85</ambient><diffuse>0.95 0.38 0.12 0.85</diffuse></material></visual>
      <gravity>1</gravity><velocity_decay /><self_collide>0</self_collide>
    </link>
    <joint name='rotor_2_joint' type='revolute'>
      <child>rotor_2</child><parent>base_link</parent>
      <axis><xyz expressed_in="__model__">0 0.1302 0.9915</xyz><limit><lower>-1e+16</lower><upper>1e+16</upper></limit><dynamics><spring_reference>0</spring_reference><spring_stiffness>0</spring_stiffness></dynamics></axis>
    </joint>

    <link name='rotor_3'>
      <pose>-1.95 4.00 0.93 0 0 0</pose>
      <inertial><mass>2.0</mass><inertia><ixx>0.49075</ixx><ixy>0</ixy><ixz>0</ixz><iyy>0.49075</iyy><iyz>0</iyz><izz>0.98129</izz></inertia></inertial>
      <collision name='rotor_3_collision'><geometry><cylinder><length>0.025</length><radius>0.9906</radius></cylinder></geometry></collision>
      <visual name='rotor_3_visual'><geometry><cylinder><length>0.025</length><radius>0.9906</radius></cylinder></geometry><material><ambient>0.95 0.38 0.12 0.85</ambient><diffuse>0.95 0.38 0.12 0.85</diffuse></material></visual>
      <gravity>1</gravity><velocity_decay /><self_collide>0</self_collide>
    </link>
    <joint name='rotor_3_joint' type='revolute'>
      <child>rotor_3</child><parent>base_link</parent>
      <axis><xyz expressed_in="__model__">0 -0.1302 0.9915</xyz><limit><lower>-1e+16</lower><upper>1e+16</upper></limit><dynamics><spring_reference>0</spring_reference><spring_stiffness>0</spring_stiffness></dynamics></axis>
    </joint>

    <link name='rotor_4'>
      <pose>-1.95 1.45 0.93 0 0 0</pose>
      <inertial><mass>2.0</mass><inertia><ixx>0.49075</ixx><ixy>0</ixy><ixz>0</ixz><iyy>0.49075</iyy><iyz>0</iyz><izz>0.98129</izz></inertia></inertial>
      <collision name='rotor_4_collision'><geometry><cylinder><length>0.025</length><radius>0.9906</radius></cylinder></geometry></collision>
      <visual name='rotor_4_visual'><geometry><cylinder><length>0.025</length><radius>0.9906</radius></cylinder></geometry><material><ambient>0.10 0.45 0.90 0.85</ambient><diffuse>0.10 0.45 0.90 0.85</diffuse></material></visual>
      <gravity>1</gravity><velocity_decay /><self_collide>0</self_collide>
    </link>
    <joint name='rotor_4_joint' type='revolute'>
      <child>rotor_4</child><parent>base_link</parent>
      <axis><xyz expressed_in="__model__">0 0.1302 0.9915</xyz><limit><lower>-1e+16</lower><upper>1e+16</upper></limit><dynamics><spring_reference>0</spring_reference><spring_stiffness>0</spring_stiffness></dynamics></axis>
    </joint>

    <link name='rotor_5'>
      <pose>-4.03 1.45 0.93 0 0 0</pose>
      <inertial><mass>2.0</mass><inertia><ixx>0.49075</ixx><ixy>0</ixy><ixz>0</ixz><iyy>0.49075</iyy><iyz>0</iyz><izz>0.98129</izz></inertia></inertial>
      <collision name='rotor_5_collision'><geometry><cylinder><length>0.025</length><radius>0.9906</radius></cylinder></geometry></collision>
      <visual name='rotor_5_visual'><geometry><cylinder><length>0.025</length><radius>0.9906</radius></cylinder></geometry><material><ambient>0.95 0.38 0.12 0.85</ambient><diffuse>0.95 0.38 0.12 0.85</diffuse></material></visual>
      <gravity>1</gravity><velocity_decay /><self_collide>0</self_collide>
    </link>
    <joint name='rotor_5_joint' type='revolute'>
      <child>rotor_5</child><parent>base_link</parent>
      <axis><xyz expressed_in="__model__">0 -0.1302 0.9915</xyz><limit><lower>-1e+16</lower><upper>1e+16</upper></limit><dynamics><spring_reference>0</spring_reference><spring_stiffness>0</spring_stiffness></dynamics></axis>
    </joint>

    <link name='rotor_6'>
      <pose>-4.03 -1.45 0.93 0 0 0</pose>
      <inertial><mass>2.0</mass><inertia><ixx>0.49075</ixx><ixy>0</ixy><ixz>0</ixz><iyy>0.49075</iyy><iyz>0</iyz><izz>0.98129</izz></inertia></inertial>
      <collision name='rotor_6_collision'><geometry><cylinder><length>0.025</length><radius>0.9906</radius></cylinder></geometry></collision>
      <visual name='rotor_6_visual'><geometry><cylinder><length>0.025</length><radius>0.9906</radius></cylinder></geometry><material><ambient>0.10 0.45 0.90 0.85</ambient><diffuse>0.10 0.45 0.90 0.85</diffuse></material></visual>
      <gravity>1</gravity><velocity_decay /><self_collide>0</self_collide>
    </link>
    <joint name='rotor_6_joint' type='revolute'>
      <child>rotor_6</child><parent>base_link</parent>
      <axis><xyz expressed_in="__model__">0 0.1302 0.9915</xyz><limit><lower>-1e+16</lower><upper>1e+16</upper></limit><dynamics><spring_reference>0</spring_reference><spring_stiffness>0</spring_stiffness></dynamics></axis>
    </joint>

    <link name='rotor_7'>
      <pose>-1.95 -1.45 0.93 0 0 0</pose>
      <inertial><mass>2.0</mass><inertia><ixx>0.49075</ixx><ixy>0</ixy><ixz>0</ixz><iyy>0.49075</iyy><iyz>0</iyz><izz>0.98129</izz></inertia></inertial>
      <collision name='rotor_7_collision'><geometry><cylinder><length>0.025</length><radius>0.9906</radius></cylinder></geometry></collision>
      <visual name='rotor_7_visual'><geometry><cylinder><length>0.025</length><radius>0.9906</radius></cylinder></geometry><material><ambient>0.95 0.38 0.12 0.85</ambient><diffuse>0.95 0.38 0.12 0.85</diffuse></material></visual>
      <gravity>1</gravity><velocity_decay /><self_collide>0</self_collide>
    </link>
    <joint name='rotor_7_joint' type='revolute'>
      <child>rotor_7</child><parent>base_link</parent>
      <axis><xyz expressed_in="__model__">0 -0.1302 0.9915</xyz><limit><lower>-1e+16</lower><upper>1e+16</upper></limit><dynamics><spring_reference>0</spring_reference><spring_stiffness>0</spring_stiffness></dynamics></axis>
    </joint>

    <link name='rotor_8'>
      <pose>-1.95 -4.00 0.93 0 0 0</pose>
      <inertial><mass>2.0</mass><inertia><ixx>0.49075</ixx><ixy>0</ixy><ixz>0</ixz><iyy>0.49075</iyy><iyz>0</iyz><izz>0.98129</izz></inertia></inertial>
      <collision name='rotor_8_collision'><geometry><cylinder><length>0.025</length><radius>0.9906</radius></cylinder></geometry></collision>
      <visual name='rotor_8_visual'><geometry><cylinder><length>0.025</length><radius>0.9906</radius></cylinder></geometry><material><ambient>0.10 0.45 0.90 0.85</ambient><diffuse>0.10 0.45 0.90 0.85</diffuse></material></visual>
      <gravity>1</gravity><velocity_decay /><self_collide>0</self_collide>
    </link>
    <joint name='rotor_8_joint' type='revolute'>
      <child>rotor_8</child><parent>base_link</parent>
      <axis><xyz expressed_in="__model__">0 0.1302 0.9915</xyz><limit><lower>-1e+16</lower><upper>1e+16</upper></limit><dynamics><spring_reference>0</spring_reference><spring_stiffness>0</spring_stiffness></dynamics></axis>
    </joint>

    <link name='rotor_9'>
      <pose>1.95 -4.00 0.93 0 0 0</pose>
      <inertial><mass>2.0</mass><inertia><ixx>0.49075</ixx><ixy>0</ixy><ixz>0</ixz><iyy>0.49075</iyy><iyz>0</iyz><izz>0.98129</izz></inertia></inertial>
      <collision name='rotor_9_collision'><geometry><cylinder><length>0.025</length><radius>0.9906</radius></cylinder></geometry></collision>
      <visual name='rotor_9_visual'><geometry><cylinder><length>0.025</length><radius>0.9906</radius></cylinder></geometry><material><ambient>0.10 0.45 0.90 0.85</ambient><diffuse>0.10 0.45 0.90 0.85</diffuse></material></visual>
      <gravity>1</gravity><velocity_decay /><self_collide>0</self_collide>
    </link>
    <joint name='rotor_9_joint' type='revolute'>
      <child>rotor_9</child><parent>base_link</parent>
      <axis><xyz expressed_in="__model__">0 -0.1302 0.9915</xyz><limit><lower>-1e+16</lower><upper>1e+16</upper></limit><dynamics><spring_reference>0</spring_reference><spring_stiffness>0</spring_stiffness></dynamics></axis>
    </joint>

    <link name='rotor_10'>
      <pose>1.95 -1.45 0.93 0 0 0</pose>
      <inertial><mass>2.0</mass><inertia><ixx>0.49075</ixx><ixy>0</ixy><ixz>0</ixz><iyy>0.49075</iyy><iyz>0</iyz><izz>0.98129</izz></inertia></inertial>
      <collision name='rotor_10_collision'><geometry><cylinder><length>0.025</length><radius>0.9906</radius></cylinder></geometry></collision>
      <visual name='rotor_10_visual'><geometry><cylinder><length>0.025</length><radius>0.9906</radius></cylinder></geometry><material><ambient>0.95 0.38 0.12 0.85</ambient><diffuse>0.95 0.38 0.12 0.85</diffuse></material></visual>
      <gravity>1</gravity><velocity_decay /><self_collide>0</self_collide>
    </link>
    <joint name='rotor_10_joint' type='revolute'>
      <child>rotor_10</child><parent>base_link</parent>
      <axis><xyz expressed_in="__model__">0 0.1302 0.9915</xyz><limit><lower>-1e+16</lower><upper>1e+16</upper></limit><dynamics><spring_reference>0</spring_reference><spring_stiffness>0</spring_stiffness></dynamics></axis>
    </joint>

    <link name='rotor_11'>
      <pose>4.03 -1.45 0.93 0 0 0</pose>
      <inertial><mass>2.0</mass><inertia><ixx>0.49075</ixx><ixy>0</ixy><ixz>0</ixz><iyy>0.49075</iyy><iyz>0</iyz><izz>0.98129</izz></inertia></inertial>
      <collision name='rotor_11_collision'><geometry><cylinder><length>0.025</length><radius>0.9906</radius></cylinder></geometry></collision>
      <visual name='rotor_11_visual'><geometry><cylinder><length>0.025</length><radius>0.9906</radius></cylinder></geometry><material><ambient>0.10 0.45 0.90 0.85</ambient><diffuse>0.10 0.45 0.90 0.85</diffuse></material></visual>
      <gravity>1</gravity><velocity_decay /><self_collide>0</self_collide>
    </link>
    <joint name='rotor_11_joint' type='revolute'>
      <child>rotor_11</child><parent>base_link</parent>
      <axis><xyz expressed_in="__model__">0 -0.1302 0.9915</xyz><limit><lower>-1e+16</lower><upper>1e+16</upper></limit><dynamics><spring_reference>0</spring_reference><spring_stiffness>0</spring_stiffness></dynamics></axis>
    </joint>

    <link name='rotor_12'>
      <pose>-1.80 0 0.45 0 -1.5707963268 0</pose>
      <inertial><mass>0.05</mass><inertia><ixx>0.0003</ixx><ixy>0</ixy><ixz>0</ixz><iyy>0.0003</iyy><iyz>0</iyz><izz>0.0006</izz></inertia></inertial>
      <collision name='rotor_12_collision'><geometry><cylinder><length>0.025</length><radius>0.28</radius></cylinder></geometry></collision>
      <visual name='rotor_12_visual'><geometry><cylinder><length>0.025</length><radius>0.28</radius></cylinder></geometry><material><ambient>0.10 0.45 0.90 0.85</ambient><diffuse>0.10 0.45 0.90 0.85</diffuse></material></visual>
      <gravity>1</gravity><velocity_decay /><self_collide>0</self_collide>
    </link>
    <joint name='rotor_12_joint' type='revolute'>
      <child>rotor_12</child><parent>base_link</parent>
      <axis><xyz expressed_in="__model__">-1 0 0</xyz><limit><lower>-1e+16</lower><upper>1e+16</upper></limit><dynamics><spring_reference>0</spring_reference><spring_stiffness>0</spring_stiffness></dynamics></axis>
    </joint>

    <link name='left_aileron'>
      <pose relative_to='base_link'>0.4 2.75 0.18 0 0 0</pose>
      <inertial><mass>0.001</mass><inertia><ixx>0.00001</ixx><ixy>0</ixy><ixz>0</ixz><iyy>0.00001</iyy><iyz>0</iyz><izz>0.00001</izz></inertia></inertial>
      <collision name='left_aileron_collision'><geometry><box><size>0.85 1.15 0.04</size></box></geometry></collision>
      <visual name='left_aileron_visual'><geometry><box><size>0.85 1.15 0.04</size></box></geometry><material><ambient>0.65 0.68 0.70 1</ambient><diffuse>0.65 0.68 0.70 1</diffuse></material></visual>
    </link>
    <link name='right_aileron'>
      <pose relative_to='base_link'>0.4 -2.75 0.18 0 0 0</pose>
      <inertial><mass>0.001</mass><inertia><ixx>0.00001</ixx><ixy>0</ixy><ixz>0</ixz><iyy>0.00001</iyy><iyz>0</iyz><izz>0.00001</izz></inertia></inertial>
      <collision name='right_aileron_collision'><geometry><box><size>0.85 1.15 0.04</size></box></geometry></collision>
      <visual name='right_aileron_visual'><geometry><box><size>0.85 1.15 0.04</size></box></geometry><material><ambient>0.65 0.68 0.70 1</ambient><diffuse>0.65 0.68 0.70 1</diffuse></material></visual>
    </link>
    <link name='elevator'>
      <pose relative_to='base_link'>-3.55 0 0.24 0 0 0</pose>
      <inertial><mass>0.001</mass><inertia><ixx>0.00001</ixx><ixy>0</ixy><ixz>0</ixz><iyy>0.00001</iyy><iyz>0</iyz><izz>0.00001</izz></inertia></inertial>
      <collision name='elevator_collision'><geometry><box><size>0.70 1.90 0.04</size></box></geometry></collision>
      <visual name='elevator_visual'><geometry><box><size>0.70 1.90 0.04</size></box></geometry><material><ambient>0.65 0.68 0.70 1</ambient><diffuse>0.65 0.68 0.70 1</diffuse></material></visual>
    </link>
    <link name='left_rudder'>
      <pose relative_to='base_link'>-3.75 0.28 0.65 0 0 0</pose>
      <inertial><mass>0.001</mass><inertia><ixx>0.00001</ixx><ixy>0</ixy><ixz>0</ixz><iyy>0.00001</iyy><iyz>0</iyz><izz>0.00001</izz></inertia></inertial>
      <collision name='left_rudder_collision'><geometry><box><size>0.65 0.04 0.75</size></box></geometry></collision>
      <visual name='left_rudder_visual'><geometry><box><size>0.65 0.04 0.75</size></box></geometry><material><ambient>0.65 0.68 0.70 1</ambient><diffuse>0.65 0.68 0.70 1</diffuse></material></visual>
    </link>
    <link name='right_rudder'>
      <pose relative_to='base_link'>-3.75 -0.28 0.65 0 0 0</pose>
      <inertial><mass>0.001</mass><inertia><ixx>0.00001</ixx><ixy>0</ixy><ixz>0</ixz><iyy>0.00001</iyy><iyz>0</iyz><izz>0.00001</izz></inertia></inertial>
      <collision name='right_rudder_collision'><geometry><box><size>0.65 0.04 0.75</size></box></geometry></collision>
      <visual name='right_rudder_visual'><geometry><box><size>0.65 0.04 0.75</size></box></geometry><material><ambient>0.65 0.68 0.70 1</ambient><diffuse>0.65 0.68 0.70 1</diffuse></material></visual>
    </link>

    <joint name='servo_0' type='revolute'>
      <parent>base_link</parent><child>left_aileron</child>
      <pose relative_to='base_link'>0.4 2.75 0.18 0 0 0</pose>
      <axis><xyz>0 1 0</xyz><limit><lower>-0.78</lower><upper>0.78</upper></limit><dynamics><damping>1.0</damping></dynamics></axis>
      <physics><ode><implicit_spring_damper>1</implicit_spring_damper></ode></physics>
    </joint>
    <joint name='servo_1' type='revolute'>
      <parent>base_link</parent><child>right_aileron</child>
      <pose relative_to='base_link'>0.4 -2.75 0.18 0 0 0</pose>
      <axis><xyz>0 1 0</xyz><limit><lower>-0.78</lower><upper>0.78</upper></limit><dynamics><damping>1.0</damping></dynamics></axis>
      <physics><ode><implicit_spring_damper>1</implicit_spring_damper></ode></physics>
    </joint>
    <joint name='servo_2' type='revolute'>
      <parent>base_link</parent><child>elevator</child>
      <pose relative_to='base_link'>-3.55 0 0.24 0 0 0</pose>
      <axis><xyz>0 1 0</xyz><limit><lower>-0.78</lower><upper>0.78</upper></limit><dynamics><damping>1.0</damping></dynamics></axis>
      <physics><ode><implicit_spring_damper>1</implicit_spring_damper></ode></physics>
    </joint>
    <joint name='servo_3' type='revolute'>
      <parent>base_link</parent><child>left_rudder</child>
      <pose relative_to='base_link'>-3.75 0.28 0.65 0 0 0</pose>
      <axis><xyz>0 0 1</xyz><limit><lower>-0.78</lower><upper>0.78</upper></limit><dynamics><damping>1.0</damping></dynamics></axis>
      <physics><ode><implicit_spring_damper>1</implicit_spring_damper></ode></physics>
    </joint>
    <joint name='servo_4' type='revolute'>
      <parent>base_link</parent><child>right_rudder</child>
      <pose relative_to='base_link'>-3.75 -0.28 0.65 0 0 0</pose>
      <axis><xyz>0 0 1</xyz><limit><lower>-0.78</lower><upper>0.78</upper></limit><dynamics><damping>1.0</damping></dynamics></axis>
      <physics><ode><implicit_spring_damper>1</implicit_spring_damper></ode></physics>
    </joint>

    <plugin filename="libAirSpeedPlugin.so" name="px4::AirSpeed">
      <link_name>base_link</link_name>
    </plugin>

    <plugin filename="gz-sim-lift-drag-system" name="gz::sim::systems::LiftDrag">
      <a0>0.05</a0><cla>4.7</cla><cda>0.6</cda><cma>0</cma><alpha_stall>0.34</alpha_stall><cla_stall>-3.85</cla_stall><cda_stall>-0.92</cda_stall><cma_stall>0</cma_stall>
      <cp>0.35 2.6 0.16</cp><area>1.4</area><air_density>1.2041</air_density><forward>1 0 0</forward><upward>0 0 1</upward><link_name>base_link</link_name><control_joint_name>servo_0</control_joint_name><control_joint_rad_to_cl>-1.0</control_joint_rad_to_cl>
    </plugin>
    <plugin filename="gz-sim-lift-drag-system" name="gz::sim::systems::LiftDrag">
      <a0>0.05</a0><cla>4.7</cla><cda>0.6</cda><cma>0</cma><alpha_stall>0.34</alpha_stall><cla_stall>-3.85</cla_stall><cda_stall>-0.92</cda_stall><cma_stall>0</cma_stall>
      <cp>0.35 -2.6 0.16</cp><area>1.4</area><air_density>1.2041</air_density><forward>1 0 0</forward><upward>0 0 1</upward><link_name>base_link</link_name><control_joint_name>servo_1</control_joint_name><control_joint_rad_to_cl>-1.0</control_joint_rad_to_cl>
    </plugin>
    <plugin filename="gz-sim-lift-drag-system" name="gz::sim::systems::LiftDrag">
      <a0>-0.2</a0><cla>4.7</cla><cda>0.6</cda><cma>0</cma><alpha_stall>0.34</alpha_stall><cla_stall>-3.85</cla_stall><cda_stall>-0.92</cda_stall><cma_stall>0</cma_stall>
      <cp>-3.55 0 0.24</cp><area>0.8</area><air_density>1.2041</air_density><forward>1 0 0</forward><upward>0 0 1</upward><link_name>base_link</link_name><control_joint_name>servo_2</control_joint_name><control_joint_rad_to_cl>-8.0</control_joint_rad_to_cl>
    </plugin>
    <plugin filename="gz-sim-lift-drag-system" name="gz::sim::systems::LiftDrag">
      <a0>0.0</a0><cla>3.5</cla><cda>0.4</cda><cma>0</cma><alpha_stall>0.34</alpha_stall><cla_stall>-2.0</cla_stall><cda_stall>-0.4</cda_stall><cma_stall>0</cma_stall>
      <cp>-3.75 0.28 0.65</cp><area>0.25</area><air_density>1.2041</air_density><forward>1 0 0</forward><upward>0 1 0</upward><link_name>base_link</link_name><control_joint_name>servo_3</control_joint_name><control_joint_rad_to_cl>4.0</control_joint_rad_to_cl>
    </plugin>
    <plugin filename="gz-sim-lift-drag-system" name="gz::sim::systems::LiftDrag">
      <a0>0.0</a0><cla>3.5</cla><cda>0.4</cda><cma>0</cma><alpha_stall>0.34</alpha_stall><cla_stall>-2.0</cla_stall><cda_stall>-0.4</cda_stall><cma_stall>0</cma_stall>
      <cp>-3.75 -0.28 0.65</cp><area>0.25</area><air_density>1.2041</air_density><forward>1 0 0</forward><upward>0 1 0</upward><link_name>base_link</link_name><control_joint_name>servo_4</control_joint_name><control_joint_rad_to_cl>4.0</control_joint_rad_to_cl>
    </plugin>

    <plugin filename="gz-sim-joint-position-controller-system" name="gz::sim::systems::JointPositionController"><joint_name>servo_0</joint_name><sub_topic>servo_0</sub_topic><p_gain>10</p_gain><i_gain>0</i_gain><d_gain>0</d_gain></plugin>
    <plugin filename="gz-sim-joint-position-controller-system" name="gz::sim::systems::JointPositionController"><joint_name>servo_1</joint_name><sub_topic>servo_1</sub_topic><p_gain>10</p_gain><i_gain>0</i_gain><d_gain>0</d_gain></plugin>
    <plugin filename="gz-sim-joint-position-controller-system" name="gz::sim::systems::JointPositionController"><joint_name>servo_2</joint_name><sub_topic>servo_2</sub_topic><p_gain>10</p_gain><i_gain>0</i_gain><d_gain>0</d_gain></plugin>
    <plugin filename="gz-sim-joint-position-controller-system" name="gz::sim::systems::JointPositionController"><joint_name>servo_3</joint_name><sub_topic>servo_3</sub_topic><p_gain>10</p_gain><i_gain>0</i_gain><d_gain>0</d_gain></plugin>
    <plugin filename="gz-sim-joint-position-controller-system" name="gz::sim::systems::JointPositionController"><joint_name>servo_4</joint_name><sub_topic>servo_4</sub_topic><p_gain>10</p_gain><i_gain>0</i_gain><d_gain>0</d_gain></plugin>

    <plugin filename="gz-sim-multicopter-motor-model-system" name="gz::sim::systems::MulticopterMotorModel"><jointName>rotor_0_joint</jointName><linkName>rotor_0</linkName><turningDirection>cw</turningDirection><timeConstantUp>0.0125</timeConstantUp><timeConstantDown>0.025</timeConstantDown><maxRotVelocity>249.23</maxRotVelocity><motorConstant>0.0371333</motorConstant><momentConstant>0.0878447</momentConstant><commandSubTopic>command/motor_speed</commandSubTopic><motorNumber>0</motorNumber><rotorDragCoefficient>8.06428e-05</rotorDragCoefficient><rollingMomentCoefficient>1e-06</rollingMomentCoefficient><rotorVelocitySlowdownSim>10</rotorVelocitySlowdownSim><motorType>velocity</motorType></plugin>
    <plugin filename="gz-sim-multicopter-motor-model-system" name="gz::sim::systems::MulticopterMotorModel"><jointName>rotor_1_joint</jointName><linkName>rotor_1</linkName><turningDirection>ccw</turningDirection><timeConstantUp>0.0125</timeConstantUp><timeConstantDown>0.025</timeConstantDown><maxRotVelocity>249.23</maxRotVelocity><motorConstant>0.0371333</motorConstant><momentConstant>0.0878447</momentConstant><commandSubTopic>command/motor_speed</commandSubTopic><motorNumber>1</motorNumber><rotorDragCoefficient>8.06428e-05</rotorDragCoefficient><rollingMomentCoefficient>1e-06</rollingMomentCoefficient><rotorVelocitySlowdownSim>10</rotorVelocitySlowdownSim><motorType>velocity</motorType></plugin>
    <plugin filename="gz-sim-multicopter-motor-model-system" name="gz::sim::systems::MulticopterMotorModel"><jointName>rotor_2_joint</jointName><linkName>rotor_2</linkName><turningDirection>cw</turningDirection><timeConstantUp>0.0125</timeConstantUp><timeConstantDown>0.025</timeConstantDown><maxRotVelocity>249.23</maxRotVelocity><motorConstant>0.0371333</motorConstant><momentConstant>0.0878447</momentConstant><commandSubTopic>command/motor_speed</commandSubTopic><motorNumber>2</motorNumber><rotorDragCoefficient>8.06428e-05</rotorDragCoefficient><rollingMomentCoefficient>1e-06</rollingMomentCoefficient><rotorVelocitySlowdownSim>10</rotorVelocitySlowdownSim><motorType>velocity</motorType></plugin>
    <plugin filename="gz-sim-multicopter-motor-model-system" name="gz::sim::systems::MulticopterMotorModel"><jointName>rotor_3_joint</jointName><linkName>rotor_3</linkName><turningDirection>cw</turningDirection><timeConstantUp>0.0125</timeConstantUp><timeConstantDown>0.025</timeConstantDown><maxRotVelocity>249.23</maxRotVelocity><motorConstant>0.0371333</motorConstant><momentConstant>0.0878447</momentConstant><commandSubTopic>command/motor_speed</commandSubTopic><motorNumber>3</motorNumber><rotorDragCoefficient>8.06428e-05</rotorDragCoefficient><rollingMomentCoefficient>1e-06</rollingMomentCoefficient><rotorVelocitySlowdownSim>10</rotorVelocitySlowdownSim><motorType>velocity</motorType></plugin>
    <plugin filename="gz-sim-multicopter-motor-model-system" name="gz::sim::systems::MulticopterMotorModel"><jointName>rotor_4_joint</jointName><linkName>rotor_4</linkName><turningDirection>ccw</turningDirection><timeConstantUp>0.0125</timeConstantUp><timeConstantDown>0.025</timeConstantDown><maxRotVelocity>249.23</maxRotVelocity><motorConstant>0.0371333</motorConstant><momentConstant>0.0878447</momentConstant><commandSubTopic>command/motor_speed</commandSubTopic><motorNumber>4</motorNumber><rotorDragCoefficient>8.06428e-05</rotorDragCoefficient><rollingMomentCoefficient>1e-06</rollingMomentCoefficient><rotorVelocitySlowdownSim>10</rotorVelocitySlowdownSim><motorType>velocity</motorType></plugin>
    <plugin filename="gz-sim-multicopter-motor-model-system" name="gz::sim::systems::MulticopterMotorModel"><jointName>rotor_5_joint</jointName><linkName>rotor_5</linkName><turningDirection>cw</turningDirection><timeConstantUp>0.0125</timeConstantUp><timeConstantDown>0.025</timeConstantDown><maxRotVelocity>249.23</maxRotVelocity><motorConstant>0.0371333</motorConstant><momentConstant>0.0878447</momentConstant><commandSubTopic>command/motor_speed</commandSubTopic><motorNumber>5</motorNumber><rotorDragCoefficient>8.06428e-05</rotorDragCoefficient><rollingMomentCoefficient>1e-06</rollingMomentCoefficient><rotorVelocitySlowdownSim>10</rotorVelocitySlowdownSim><motorType>velocity</motorType></plugin>
    <plugin filename="gz-sim-multicopter-motor-model-system" name="gz::sim::systems::MulticopterMotorModel"><jointName>rotor_6_joint</jointName><linkName>rotor_6</linkName><turningDirection>ccw</turningDirection><timeConstantUp>0.0125</timeConstantUp><timeConstantDown>0.025</timeConstantDown><maxRotVelocity>249.23</maxRotVelocity><motorConstant>0.0371333</motorConstant><momentConstant>0.0878447</momentConstant><commandSubTopic>command/motor_speed</commandSubTopic><motorNumber>6</motorNumber><rotorDragCoefficient>8.06428e-05</rotorDragCoefficient><rollingMomentCoefficient>1e-06</rollingMomentCoefficient><rotorVelocitySlowdownSim>10</rotorVelocitySlowdownSim><motorType>velocity</motorType></plugin>
    <plugin filename="gz-sim-multicopter-motor-model-system" name="gz::sim::systems::MulticopterMotorModel"><jointName>rotor_7_joint</jointName><linkName>rotor_7</linkName><turningDirection>cw</turningDirection><timeConstantUp>0.0125</timeConstantUp><timeConstantDown>0.025</timeConstantDown><maxRotVelocity>249.23</maxRotVelocity><motorConstant>0.0371333</motorConstant><momentConstant>0.0878447</momentConstant><commandSubTopic>command/motor_speed</commandSubTopic><motorNumber>7</motorNumber><rotorDragCoefficient>8.06428e-05</rotorDragCoefficient><rollingMomentCoefficient>1e-06</rollingMomentCoefficient><rotorVelocitySlowdownSim>10</rotorVelocitySlowdownSim><motorType>velocity</motorType></plugin>
    <plugin filename="gz-sim-multicopter-motor-model-system" name="gz::sim::systems::MulticopterMotorModel"><jointName>rotor_8_joint</jointName><linkName>rotor_8</linkName><turningDirection>ccw</turningDirection><timeConstantUp>0.0125</timeConstantUp><timeConstantDown>0.025</timeConstantDown><maxRotVelocity>249.23</maxRotVelocity><motorConstant>0.0371333</motorConstant><momentConstant>0.0878447</momentConstant><commandSubTopic>command/motor_speed</commandSubTopic><motorNumber>8</motorNumber><rotorDragCoefficient>8.06428e-05</rotorDragCoefficient><rollingMomentCoefficient>1e-06</rollingMomentCoefficient><rotorVelocitySlowdownSim>10</rotorVelocitySlowdownSim><motorType>velocity</motorType></plugin>
    <plugin filename="gz-sim-multicopter-motor-model-system" name="gz::sim::systems::MulticopterMotorModel"><jointName>rotor_9_joint</jointName><linkName>rotor_9</linkName><turningDirection>ccw</turningDirection><timeConstantUp>0.0125</timeConstantUp><timeConstantDown>0.025</timeConstantDown><maxRotVelocity>249.23</maxRotVelocity><motorConstant>0.0371333</motorConstant><momentConstant>0.0878447</momentConstant><commandSubTopic>command/motor_speed</commandSubTopic><motorNumber>9</motorNumber><rotorDragCoefficient>8.06428e-05</rotorDragCoefficient><rollingMomentCoefficient>1e-06</rollingMomentCoefficient><rotorVelocitySlowdownSim>10</rotorVelocitySlowdownSim><motorType>velocity</motorType></plugin>
    <plugin filename="gz-sim-multicopter-motor-model-system" name="gz::sim::systems::MulticopterMotorModel"><jointName>rotor_10_joint</jointName><linkName>rotor_10</linkName><turningDirection>cw</turningDirection><timeConstantUp>0.0125</timeConstantUp><timeConstantDown>0.025</timeConstantDown><maxRotVelocity>249.23</maxRotVelocity><motorConstant>0.0371333</motorConstant><momentConstant>0.0878447</momentConstant><commandSubTopic>command/motor_speed</commandSubTopic><motorNumber>10</motorNumber><rotorDragCoefficient>8.06428e-05</rotorDragCoefficient><rollingMomentCoefficient>1e-06</rollingMomentCoefficient><rotorVelocitySlowdownSim>10</rotorVelocitySlowdownSim><motorType>velocity</motorType></plugin>
    <plugin filename="gz-sim-multicopter-motor-model-system" name="gz::sim::systems::MulticopterMotorModel"><jointName>rotor_11_joint</jointName><linkName>rotor_11</linkName><turningDirection>ccw</turningDirection><timeConstantUp>0.0125</timeConstantUp><timeConstantDown>0.025</timeConstantDown><maxRotVelocity>249.23</maxRotVelocity><motorConstant>0.0371333</motorConstant><momentConstant>0.0878447</momentConstant><commandSubTopic>command/motor_speed</commandSubTopic><motorNumber>11</motorNumber><rotorDragCoefficient>8.06428e-05</rotorDragCoefficient><rollingMomentCoefficient>1e-06</rollingMomentCoefficient><rotorVelocitySlowdownSim>10</rotorVelocitySlowdownSim><motorType>velocity</motorType></plugin>
    <plugin filename="gz-sim-multicopter-motor-model-system" name="gz::sim::systems::MulticopterMotorModel"><jointName>rotor_12_joint</jointName><linkName>rotor_12</linkName><turningDirection>ccw</turningDirection><timeConstantUp>0.0125</timeConstantUp><timeConstantDown>0.025</timeConstantDown><maxRotVelocity>1000.0</maxRotVelocity><motorConstant>8.54858e-05</motorConstant><momentConstant>0.01</momentConstant><commandSubTopic>command/motor_speed</commandSubTopic><motorNumber>12</motorNumber><rotorDragCoefficient>8.06428e-05</rotorDragCoefficient><rollingMomentCoefficient>1e-06</rollingMomentCoefficient><rotorVelocitySlowdownSim>10</rotorVelocitySlowdownSim><motorType>velocity</motorType></plugin>
  </model>
</sdf>
