<?xml version="1.0" encoding="UTF-8"?>
<sdf version='1.10'>
  <model name='teTra_mk-7_EM2'>
    <pose>0 0 0.80 0 0 0</pose>
    <self_collide>false</self_collide>
    <static>false</static>

    <link name='base_link'>
      <enable_wind>true</enable_wind>
      <pose>0 0 0 0 0 0</pose>
      <inertial>
        <!-- CG fix: CoM moved to PX4's assumed CG (0,0,-0.20) so gz physics match CA_ROTOR positions.
             Was (0.0785219319, 0, -0.4030751491). All 13 rotors' gz->FRD now equal CA_ROTOR (pusher 0.45 m
             above new CG == CA_ROTOR12_PZ=-0.45). Inertia tensor kept (parallel-axis shift ~1%). -->
        <pose>0 0 -0.20 0 0 0</pose>
        <mass>1293.575</mass>
        <inertia>
          <ixx>4393.261707</ixx>
          <ixy>0.000000</ixy>
          <ixz>-132.340036</ixz>
          <iyy>4262.626834</iyy>
          <iyz>-0.000000</iyz>
          <izz>8561.621614</izz>
        </inertia>
      </inertial>
      <collision name='fuselage_collision'>
        <!-- Shortened rear for pusher clearance: was 4.8 long centered at x=0 (rear -2.4 overlapped the
             pusher disc rotor_12 at x=-1.80, r=0.9). Now 3.8 long centered at x=+0.5 -> rear -1.4 (0.4 m
             clearance ahead of the pusher), nose +2.4 unchanged. Box has no mass -> CG unaffected. -->
        <pose>0.5 0 0 0 0 0</pose>
        <geometry>
          <box>
            <size>3.8 0.5 0.45</size>
          </box>
        </geometry>
        <surface>
          <contact>
            <ode>
              <kp>100000</kp>
              <kd>1.0</kd>
              <max_vel>0.1</max_vel>
              <min_depth>0.001</min_depth>
            </ode>
          </contact>
          <friction>
            <ode />
          </friction>
        </surface>
      </collision>
      <visual name='fuselage_visual'>
        <!-- Shortened rear for pusher clearance (see fuselage_collision). 3.8 long, centered x=+0.5. -->
        <pose>0.5 0 0 0 0 0</pose>
        <geometry>
          <box>
            <size>3.8 0.5 0.45</size>
          </box>
        </geometry>
        <material>
          <ambient>0.17 0.18 0.20 1</ambient>
          <diffuse>0.17 0.18 0.20 1</diffuse>
        </material>
      </visual>
      <!-- Simple fixed landing gear from CAD: 2.1 m wheelbase, 1.8 m main track, 15 in main wheels. -->
      <collision name='main_landing_gear_left_strut_collision'>
        <pose>-1.10 0.90 -0.380 0 0 0</pose>
        <geometry><box><size>0.080 0.080 0.460</size></box></geometry>
      </collision>
      <visual name='main_landing_gear_left_strut_visual'>
        <pose>-1.10 0.90 -0.380 0 0 0</pose>
        <geometry><box><size>0.080 0.080 0.460</size></box></geometry>
        <material><ambient>0.42 0.43 0.43 1</ambient><diffuse>0.42 0.43 0.43 1</diffuse></material>
      </visual>
      <collision name='main_landing_gear_right_strut_collision'>
        <pose>-1.10 -0.90 -0.380 0 0 0</pose>
        <geometry><box><size>0.080 0.080 0.460</size></box></geometry>
      </collision>
      <visual name='main_landing_gear_right_strut_visual'>
        <pose>-1.10 -0.90 -0.380 0 0 0</pose>
        <geometry><box><size>0.080 0.080 0.460</size></box></geometry>
        <material><ambient>0.42 0.43 0.43 1</ambient><diffuse>0.42 0.43 0.43 1</diffuse></material>
      </visual>
      <collision name='nose_landing_gear_strut_collision'>
        <pose>1.00 0 -0.400 0 0 0</pose>
        <geometry><box><size>0.080 0.080 0.500</size></box></geometry>
      </collision>
      <visual name='nose_landing_gear_strut_visual'>
        <pose>1.00 0 -0.400 0 0 0</pose>
        <geometry><box><size>0.080 0.080 0.500</size></box></geometry>
        <material><ambient>0.42 0.43 0.43 1</ambient><diffuse>0.42 0.43 0.43 1</diffuse></material>
      </visual>
      <collision name='main_landing_gear_left_wheel_collision'>
        <pose>-1.10 0.90 -0.6095 1.5707963268 0 0</pose>
        <geometry><cylinder><length>0.1696</length><radius>0.1905</radius></cylinder></geometry>
        <surface>
          <contact><ode><kp>1000000</kp><kd>10</kd><max_vel>0.1</max_vel><min_depth>0.001</min_depth></ode></contact>
          <friction><ode><mu>0.8</mu><mu2>0.8</mu2></ode></friction>
        </surface>
      </collision>
      <visual name='main_landing_gear_left_wheel_visual'>
        <pose>-1.10 0.90 -0.6095 1.5707963268 0 0</pose>
        <geometry><cylinder><length>0.1696</length><radius>0.1905</radius></cylinder></geometry>
        <material><ambient>0.03 0.03 0.03 1</ambient><diffuse>0.03 0.03 0.03 1</diffuse></material>
      </visual>
      <collision name='main_landing_gear_right_wheel_collision'>
        <pose>-1.10 -0.90 -0.6095 1.5707963268 0 0</pose>
        <geometry><cylinder><length>0.1696</length><radius>0.1905</radius></cylinder></geometry>
        <surface>
          <contact><ode><kp>1000000</kp><kd>10</kd><max_vel>0.1</max_vel><min_depth>0.001</min_depth></ode></contact>
          <friction><ode><mu>0.8</mu><mu2>0.8</mu2></ode></friction>
        </surface>
      </collision>
      <visual name='main_landing_gear_right_wheel_visual'>
        <pose>-1.10 -0.90 -0.6095 1.5707963268 0 0</pose>
        <geometry><cylinder><length>0.1696</length><radius>0.1905</radius></cylinder></geometry>
        <material><ambient>0.03 0.03 0.03 1</ambient><diffuse>0.03 0.03 0.03 1</diffuse></material>
      </visual>
      <collision name='nose_landing_gear_wheel_collision'>
        <pose>1.00 0 -0.6476 1.5707963268 0 0</pose>
        <geometry><cylinder><length>0.1800</length><radius>0.1524</radius></cylinder></geometry>
        <surface>
          <contact><ode><kp>1000000</kp><kd>10</kd><max_vel>0.1</max_vel><min_depth>0.001</min_depth></ode></contact>
          <friction><ode><mu>0.8</mu><mu2>0.8</mu2></ode></friction>
        </surface>
      </collision>
      <visual name='nose_landing_gear_wheel_visual'>
        <pose>1.00 0 -0.6476 1.5707963268 0 0</pose>
        <geometry><cylinder><length>0.1800</length><radius>0.1524</radius></cylinder></geometry>
        <material><ambient>0.03 0.03 0.03 1</ambient><diffuse>0.03 0.03 0.03 1</diffuse></material>
      </visual>
      <visual name='main_wing_visual'>
        <pose>-0.135 0 0.730 0 0 0</pose>
        <geometry>
          <box>
            <size>1.500 8.000 0.255</size>
          </box>
        </geometry>
        <material>
          <ambient>0.24 0.27 0.29 1</ambient>
          <diffuse>0.24 0.27 0.29 1</diffuse>
        </material>
      </visual>
      <visual name='left_tail_boom_visual'>
        <pose>-2.789 1.45 0.760 0 0 0</pose>
        <geometry><box><size>4.708 0.240 0.240</size></box></geometry>
        <material><ambient>0.14 0.15 0.16 1</ambient>
          <diffuse>0.14 0.15 0.16 1</diffuse></material>
      </visual>
      <visual name='right_tail_boom_visual'>
        <pose>-2.789 -1.45 0.760 0 0 0</pose>
        <geometry><box><size>4.708 0.240 0.240</size></box></geometry>
        <material><ambient>0.14 0.15 0.16 1</ambient>
          <diffuse>0.14 0.15 0.16 1</diffuse></material>
      </visual>
      <visual name='horizontal_tail_visual'>
        <pose>-5.143 0 0.760 0 0 0</pose>
        <geometry>
          <box>
            <size>0.716 2.900 0.086</size>
          </box>
        </geometry>
        <material>
          <ambient>0.24 0.27 0.29 1</ambient>
          <diffuse>0.24 0.27 0.29 1</diffuse>
        </material>
      </visual>
      <visual name='right_vertical_tail_visual'>
        <pose>-5.503 1.45 0.358 0 0 0</pose>
        <geometry><box><size>0.720 0.040 0.564</size></box></geometry>
        <material><ambient>0.24 0.27 0.29 1</ambient><diffuse>0.24 0.27 0.29 1</diffuse></material>
      </visual>
      <visual name='left_vertical_tail_visual'>
        <pose>-5.503 -1.45 0.358 0 0 0</pose>
        <geometry><box><size>0.720 0.040 0.564</size></box></geometry>
        <material><ambient>0.24 0.27 0.29 1</ambient><diffuse>0.24 0.27 0.29 1</diffuse></material>
      </visual>
      <visual name='left_motor_beam_inner'>
        <pose>0 1.45 0.760 0 0 0</pose>
        <geometry>
          <box>
            <size>8.30 0.240 0.240</size>
          </box>
        </geometry>
        <material>
          <ambient>0.09 0.09 0.10 1</ambient>
          <diffuse>0.09 0.09 0.10 1</diffuse>
        </material>
      </visual>
      <visual name='right_motor_beam_inner'>
        <pose>0 -1.45 0.760 0 0 0</pose>
        <geometry>
          <box>
            <size>8.30 0.240 0.240</size>
          </box>
        </geometry>
        <material>
          <ambient>0.09 0.09 0.10 1</ambient>
          <diffuse>0.09 0.09 0.10 1</diffuse>
        </material>
      </visual>
      <visual name='left_motor_beam_outer'>
        <pose>0 4.0 0.760 0 0 0</pose>
        <geometry>
          <box>
            <size>4.10 0.240 0.240</size>
          </box>
        </geometry>
        <material>
          <ambient>0.09 0.09 0.10 1</ambient>
          <diffuse>0.09 0.09 0.10 1</diffuse>
        </material>
      </visual>
      <visual name='right_motor_beam_outer'>
        <pose>0 -4.0 0.760 0 0 0</pose>
        <geometry>
          <box>
            <size>4.10 0.240 0.240</size>
          </box>
        </geometry>
        <material>
          <ambient>0.09 0.09 0.10 1</ambient>
          <diffuse>0.09 0.09 0.10 1</diffuse>
        </material>
      </visual>
      <gravity>1</gravity>
      <velocity_decay />
      <self_collide>0</self_collide>

      <sensor name="imu_sensor" type="imu">
        <always_on>1</always_on>
        <update_rate>250</update_rate>
        <imu>
          <angular_velocity>
            <x>
              <noise type="gaussian">
                <mean>0</mean>
                <stddev>0.0003394</stddev>
                <dynamic_bias_stddev>3.8785e-05</dynamic_bias_stddev>
                <dynamic_bias_correlation_time>1000</dynamic_bias_correlation_time>
              </noise>
            </x>
            <y>
              <noise type="gaussian">
                <mean>0</mean>
                <stddev>0.0003394</stddev>
                <dynamic_bias_stddev>3.8785e-05</dynamic_bias_stddev>
                <dynamic_bias_correlation_time>1000</dynamic_bias_correlation_time>
              </noise>
            </y>
            <z>
              <noise type="gaussian">
                <mean>0</mean>
                <stddev>0.0003394</stddev>
                <dynamic_bias_stddev>3.8785e-05</dynamic_bias_stddev>
                <dynamic_bias_correlation_time>1000</dynamic_bias_correlation_time>
              </noise>
            </z>
          </angular_velocity>
          <linear_acceleration>
            <x>
              <noise type="gaussian">
                <mean>0</mean>
                <stddev>0.004</stddev>
                <dynamic_bias_stddev>0.006</dynamic_bias_stddev>
                <dynamic_bias_correlation_time>300</dynamic_bias_correlation_time>
              </noise>
            </x>
            <y>
              <noise type="gaussian">
                <mean>0</mean>
                <stddev>0.004</stddev>
                <dynamic_bias_stddev>0.006</dynamic_bias_stddev>
                <dynamic_bias_correlation_time>300</dynamic_bias_correlation_time>
              </noise>
            </y>
            <z>
              <noise type="gaussian">
                <mean>0</mean>
                <stddev>0.004</stddev>
                <dynamic_bias_stddev>0.006</dynamic_bias_stddev>
                <dynamic_bias_correlation_time>300</dynamic_bias_correlation_time>
              </noise>
            </z>
          </linear_acceleration>
        </imu>
      </sensor>
      <sensor name="air_pressure_sensor" type="air_pressure">
        <always_on>1</always_on>
        <update_rate>50</update_rate>
        <air_pressure>
          <pressure>
            <noise type="gaussian">
              <mean>0</mean>
              <stddev>0.01</stddev>
            </noise>
          </pressure>
        </air_pressure>
      </sensor>
      <sensor name="magnetometer_sensor" type="magnetometer">
        <always_on>1</always_on>
        <update_rate>100</update_rate>
        <magnetometer>
          <x>
            <noise type="gaussian">
              <stddev>0.0001</stddev>
            </noise>
          </x>
          <y>
            <noise type="gaussian">
              <stddev>0.0001</stddev>
            </noise>
          </y>
          <z>
            <noise type="gaussian">
              <stddev>0.0001</stddev>
            </noise>
          </z>
        </magnetometer>
      </sensor>
      <sensor name="navsat_sensor" type="navsat">
        <always_on>1</always_on>
        <update_rate>30</update_rate>
      </sensor>
      <!-- Chase camera on a rigid boom behind+above the vehicle (tail-chase view),
           with an on-board video recorder triggered via the /chase/record_video service. -->
      <sensor name="chase_cam" type="camera">
        <pose>-11 0 4.2 0 0.34 0</pose>
        <camera>
          <horizontal_fov>1.05</horizontal_fov>
          <image><width>1280</width><height>720</height></image>
          <clip><near>0.1</near><far>4000</far></clip>
        </camera>
        <always_on>1</always_on>
        <update_rate>25</update_rate>
        <topic>chase_cam</topic>
        <plugin filename="gz-sim-camera-video-recorder-system" name="gz::sim::systems::CameraVideoRecorder">
          <service>/chase/record_video</service>
          <fps>25</fps>
        </plugin>
      </sensor>
    </link>

    <!-- H4T130 motor (13.2 kg) + ESC (2.3 kg) masses. ESC position is assumed colocated with the motor. -->
    <link name='motor_esc_0'>
      <pose>4.03 1.45 0.93 0 0 0</pose>
      <inertial>
        <pose>0 0 0 0 0 0</pose>
        <mass>15.5</mass>
        <inertia>
          <ixx>0.07546</ixx>
          <ixy>0</ixy>
          <ixz>0</ixz>
          <iyy>0.08136</iyy>
          <iyz>0</iyz>
          <izz>0.12040</izz>
        </inertia>
      </inertial>
    </link>
    <joint name='motor_esc_0_joint' type='fixed'>
      <parent>base_link</parent>
      <child>motor_esc_0</child>
    </joint>

    <link name='motor_esc_1'>
      <pose>1.95 1.45 0.93 0 0 0</pose>
      <inertial>
        <pose>0 0 0 0 0 0</pose>
        <mass>15.5</mass>
        <inertia>
          <ixx>0.07546</ixx>
          <ixy>0</ixy>
          <ixz>0</ixz>
          <iyy>0.08136</iyy>
          <iyz>0</iyz>
          <izz>0.12040</izz>
        </inertia>
      </inertial>
    </link>
    <joint name='motor_esc_1_joint' type='fixed'>
      <parent>base_link</parent>
      <child>motor_esc_1</child>
    </joint>

    <link name='motor_esc_2'>
      <pose>1.95 4.00 0.93 0 0 0</pose>
      <inertial>
        <pose>0 0 0 0 0 0</pose>
        <mass>15.5</mass>
        <inertia>
          <ixx>0.07546</ixx>
          <ixy>0</ixy>
          <ixz>0</ixz>
          <iyy>0.08136</iyy>
          <iyz>0</iyz>
          <izz>0.12040</izz>
        </inertia>
      </inertial>
    </link>
    <joint name='motor_esc_2_joint' type='fixed'>
      <parent>base_link</parent>
      <child>motor_esc_2</child>
    </joint>

    <link name='motor_esc_3'>
      <pose>-1.95 4.00 0.93 0 0 0</pose>
      <inertial>
        <pose>0 0 0 0 0 0</pose>
        <mass>15.5</mass>
        <inertia>
          <ixx>0.07546</ixx>
          <ixy>0</ixy>
          <ixz>0</ixz>
          <iyy>0.08136</iyy>
          <iyz>0</iyz>
          <izz>0.12040</izz>
        </inertia>
      </inertial>
    </link>
    <joint name='motor_esc_3_joint' type='fixed'>
      <parent>base_link</parent>
      <child>motor_esc_3</child>
    </joint>

    <link name='motor_esc_4'>
      <pose>-1.95 1.45 0.93 0 0 0</pose>
      <inertial>
        <pose>0 0 0 0 0 0</pose>
        <mass>15.5</mass>
        <inertia>
          <ixx>0.07546</ixx>
          <ixy>0</ixy>
          <ixz>0</ixz>
          <iyy>0.08136</iyy>
          <iyz>0</iyz>
          <izz>0.12040</izz>
        </inertia>
      </inertial>
    </link>
    <joint name='motor_esc_4_joint' type='fixed'>
      <parent>base_link</parent>
      <child>motor_esc_4</child>
    </joint>

    <link name='motor_esc_5'>
      <pose>-4.03 1.45 0.93 0 0 0</pose>
      <inertial>
        <pose>0 0 0 0 0 0</pose>
        <mass>15.5</mass>
        <inertia>
          <ixx>0.07546</ixx>
          <ixy>0</ixy>
          <ixz>0</ixz>
          <iyy>0.08136</iyy>
          <iyz>0</iyz>
          <izz>0.12040</izz>
        </inertia>
      </inertial>
    </link>
    <joint name='motor_esc_5_joint' type='fixed'>
      <parent>base_link</parent>
      <child>motor_esc_5</child>
    </joint>

    <link name='motor_esc_6'>
      <pose>-4.03 -1.45 0.93 0 0 0</pose>
      <inertial>
        <pose>0 0 0 0 0 0</pose>
        <mass>15.5</mass>
        <inertia>
          <ixx>0.07546</ixx>
          <ixy>0</ixy>
          <ixz>0</ixz>
          <iyy>0.08136</iyy>
          <iyz>0</iyz>
          <izz>0.12040</izz>
        </inertia>
      </inertial>
    </link>
    <joint name='motor_esc_6_joint' type='fixed'>
      <parent>base_link</parent>
      <child>motor_esc_6</child>
    </joint>

    <link name='motor_esc_7'>
      <pose>-1.95 -1.45 0.93 0 0 0</pose>
      <inertial>
        <pose>0 0 0 0 0 0</pose>
        <mass>15.5</mass>
        <inertia>
          <ixx>0.07546</ixx>
          <ixy>0</ixy>
          <ixz>0</ixz>
          <iyy>0.08136</iyy>
          <iyz>0</iyz>
          <izz>0.12040</izz>
        </inertia>
      </inertial>
    </link>
    <joint name='motor_esc_7_joint' type='fixed'>
      <parent>base_link</parent>
      <child>motor_esc_7</child>
    </joint>

    <link name='motor_esc_8'>
      <pose>-1.95 -4.00 0.93 0 0 0</pose>
      <inertial>
        <pose>0 0 0 0 0 0</pose>
        <mass>15.5</mass>
        <inertia>
          <ixx>0.07546</ixx>
          <ixy>0</ixy>
          <ixz>0</ixz>
          <iyy>0.08136</iyy>
          <iyz>0</iyz>
          <izz>0.12040</izz>
        </inertia>
      </inertial>
    </link>
    <joint name='motor_esc_8_joint' type='fixed'>
      <parent>base_link</parent>
      <child>motor_esc_8</child>
    </joint>

    <link name='motor_esc_9'>
      <pose>1.95 -4.00 0.93 0 0 0</pose>
      <inertial>
        <pose>0 0 0 0 0 0</pose>
        <mass>15.5</mass>
        <inertia>
          <ixx>0.07546</ixx>
          <ixy>0</ixy>
          <ixz>0</ixz>
          <iyy>0.08136</iyy>
          <iyz>0</iyz>
          <izz>0.12040</izz>
        </inertia>
      </inertial>
    </link>
    <joint name='motor_esc_9_joint' type='fixed'>
      <parent>base_link</parent>
      <child>motor_esc_9</child>
    </joint>

    <link name='motor_esc_10'>
      <pose>1.95 -1.45 0.93 0 0 0</pose>
      <inertial>
        <pose>0 0 0 0 0 0</pose>
        <mass>15.5</mass>
        <inertia>
          <ixx>0.07546</ixx>
          <ixy>0</ixy>
          <ixz>0</ixz>
          <iyy>0.08136</iyy>
          <iyz>0</iyz>
          <izz>0.12040</izz>
        </inertia>
      </inertial>
    </link>
    <joint name='motor_esc_10_joint' type='fixed'>
      <parent>base_link</parent>
      <child>motor_esc_10</child>
    </joint>

    <link name='motor_esc_11'>
      <pose>4.03 -1.45 0.93 0 0 0</pose>
      <inertial>
        <pose>0 0 0 0 0 0</pose>
        <mass>15.5</mass>
        <inertia>
          <ixx>0.07546</ixx>
          <ixy>0</ixy>
          <ixz>0</ixz>
          <iyy>0.08136</iyy>
          <iyz>0</iyz>
          <izz>0.12040</izz>
        </inertia>
      </inertial>
    </link>
    <joint name='motor_esc_11_joint' type='fixed'>
      <parent>base_link</parent>
      <child>motor_esc_11</child>
    </joint>
    <link name='rotor_0'>
      <pose>4.03 1.45 0.93 -0.1396263402 0 0</pose>
      <inertial><mass>2.0</mass><inertia><ixx>0.49075</ixx><ixy>0</ixy><ixz>0</ixz><iyy>0.49075</iyy><iyz>0</iyz><izz>0.98129</izz></inertia></inertial>
      <collision name='rotor_0_collision'><geometry><cylinder><length>0.025</length><radius>0.9906</radius></cylinder></geometry></collision>
      <visual name='rotor_0_visual'><geometry><cylinder><length>0.025</length><radius>0.9906</radius></cylinder></geometry><material><ambient>0.95 0.38 0.12 0.85</ambient><diffuse>0.95 0.38 0.12 0.85</diffuse></material></visual>
      <visual name='rotor_0_blades_visual'><pose>0 0 0.020 0 0 0</pose><geometry><box><size>1.650 0.070 0.014</size></box></geometry><material><ambient>0.95 0.38 0.12 1</ambient><diffuse>0.95 0.38 0.12 1</diffuse></material></visual>
      <visual name='rotor_0_tip_marker_visual'><pose>0.780 0.090 0.030 0 0 0</pose><geometry><box><size>0.140 0.050 0.020</size></box></geometry><material><ambient>1 1 1 1</ambient><diffuse>1 1 1 1</diffuse></material></visual>
      <gravity>1</gravity><velocity_decay /><self_collide>0</self_collide>
    </link>
    <joint name='rotor_0_joint' type='revolute'>
      <child>rotor_0</child><parent>base_link</parent>
      <axis><xyz expressed_in="__model__">0 0.13917 0.99027</xyz><limit><lower>-1e+16</lower><upper>1e+16</upper></limit><dynamics><spring_reference>0</spring_reference><spring_stiffness>0</spring_stiffness></dynamics></axis>
    </joint>

    <link name='rotor_1'>
      <pose>1.95 1.45 0.93 0.1396263402 0 0</pose>
      <inertial><mass>2.0</mass><inertia><ixx>0.49075</ixx><ixy>0</ixy><ixz>0</ixz><iyy>0.49075</iyy><iyz>0</iyz><izz>0.98129</izz></inertia></inertial>
      <collision name='rotor_1_collision'><geometry><cylinder><length>0.025</length><radius>0.9906</radius></cylinder></geometry></collision>
      <visual name='rotor_1_visual'><geometry><cylinder><length>0.025</length><radius>0.9906</radius></cylinder></geometry><material><ambient>0.10 0.45 0.90 0.85</ambient><diffuse>0.10 0.45 0.90 0.85</diffuse></material></visual>
      <visual name='rotor_1_blades_visual'><pose>0 0 0.020 0 0 0</pose><geometry><box><size>1.650 0.070 0.014</size></box></geometry><material><ambient>0.10 0.45 0.90 1</ambient><diffuse>0.10 0.45 0.90 1</diffuse></material></visual>
      <visual name='rotor_1_tip_marker_visual'><pose>0.780 0.090 0.030 0 0 0</pose><geometry><box><size>0.140 0.050 0.020</size></box></geometry><material><ambient>1 1 1 1</ambient><diffuse>1 1 1 1</diffuse></material></visual>
      <gravity>1</gravity><velocity_decay /><self_collide>0</self_collide>
    </link>
    <joint name='rotor_1_joint' type='revolute'>
      <child>rotor_1</child><parent>base_link</parent>
      <axis><xyz expressed_in="__model__">0 -0.13917 0.99027</xyz><limit><lower>-1e+16</lower><upper>1e+16</upper></limit><dynamics><spring_reference>0</spring_reference><spring_stiffness>0</spring_stiffness></dynamics></axis>
    </joint>

    <link name='rotor_2'>
      <pose>1.95 4.00 0.93 -0.1396263402 0 0</pose>
      <inertial><mass>2.0</mass><inertia><ixx>0.49075</ixx><ixy>0</ixy><ixz>0</ixz><iyy>0.49075</iyy><iyz>0</iyz><izz>0.98129</izz></inertia></inertial>
      <collision name='rotor_2_collision'><geometry><cylinder><length>0.025</length><radius>0.9906</radius></cylinder></geometry></collision>
      <visual name='rotor_2_visual'><geometry><cylinder><length>0.025</length><radius>0.9906</radius></cylinder></geometry><material><ambient>0.95 0.38 0.12 0.85</ambient><diffuse>0.95 0.38 0.12 0.85</diffuse></material></visual>
      <visual name='rotor_2_blades_visual'><pose>0 0 0.020 0 0 0</pose><geometry><box><size>1.650 0.070 0.014</size></box></geometry><material><ambient>0.95 0.38 0.12 1</ambient><diffuse>0.95 0.38 0.12 1</diffuse></material></visual>
      <visual name='rotor_2_tip_marker_visual'><pose>0.780 0.090 0.030 0 0 0</pose><geometry><box><size>0.140 0.050 0.020</size></box></geometry><material><ambient>1 1 1 1</ambient><diffuse>1 1 1 1</diffuse></material></visual>
      <gravity>1</gravity><velocity_decay /><self_collide>0</self_collide>
    </link>
    <joint name='rotor_2_joint' type='revolute'>
      <child>rotor_2</child><parent>base_link</parent>
      <axis><xyz expressed_in="__model__">0 0.13917 0.99027</xyz><limit><lower>-1e+16</lower><upper>1e+16</upper></limit><dynamics><spring_reference>0</spring_reference><spring_stiffness>0</spring_stiffness></dynamics></axis>
    </joint>

    <link name='rotor_3'>
      <pose>-1.95 4.00 0.93 0.1396263402 0 0</pose>
      <inertial><mass>2.0</mass><inertia><ixx>0.49075</ixx><ixy>0</ixy><ixz>0</ixz><iyy>0.49075</iyy><iyz>0</iyz><izz>0.98129</izz></inertia></inertial>
      <collision name='rotor_3_collision'><geometry><cylinder><length>0.025</length><radius>0.9906</radius></cylinder></geometry></collision>
      <visual name='rotor_3_visual'><geometry><cylinder><length>0.025</length><radius>0.9906</radius></cylinder></geometry><material><ambient>0.95 0.38 0.12 0.85</ambient><diffuse>0.95 0.38 0.12 0.85</diffuse></material></visual>
      <visual name='rotor_3_blades_visual'><pose>0 0 0.020 0 0 0</pose><geometry><box><size>1.650 0.070 0.014</size></box></geometry><material><ambient>0.95 0.38 0.12 1</ambient><diffuse>0.95 0.38 0.12 1</diffuse></material></visual>
      <visual name='rotor_3_tip_marker_visual'><pose>0.780 0.090 0.030 0 0 0</pose><geometry><box><size>0.140 0.050 0.020</size></box></geometry><material><ambient>1 1 1 1</ambient><diffuse>1 1 1 1</diffuse></material></visual>
      <gravity>1</gravity><velocity_decay /><self_collide>0</self_collide>
    </link>
    <joint name='rotor_3_joint' type='revolute'>
      <child>rotor_3</child><parent>base_link</parent>
      <axis><xyz expressed_in="__model__">0 -0.13917 0.99027</xyz><limit><lower>-1e+16</lower><upper>1e+16</upper></limit><dynamics><spring_reference>0</spring_reference><spring_stiffness>0</spring_stiffness></dynamics></axis>
    </joint>

    <link name='rotor_4'>
      <pose>-1.95 1.45 0.93 -0.1396263402 0 0</pose>
      <inertial><mass>2.0</mass><inertia><ixx>0.49075</ixx><ixy>0</ixy><ixz>0</ixz><iyy>0.49075</iyy><iyz>0</iyz><izz>0.98129</izz></inertia></inertial>
      <collision name='rotor_4_collision'><geometry><cylinder><length>0.025</length><radius>0.9906</radius></cylinder></geometry></collision>
      <visual name='rotor_4_visual'><geometry><cylinder><length>0.025</length><radius>0.9906</radius></cylinder></geometry><material><ambient>0.10 0.45 0.90 0.85</ambient><diffuse>0.10 0.45 0.90 0.85</diffuse></material></visual>
      <visual name='rotor_4_blades_visual'><pose>0 0 0.020 0 0 0</pose><geometry><box><size>1.650 0.070 0.014</size></box></geometry><material><ambient>0.10 0.45 0.90 1</ambient><diffuse>0.10 0.45 0.90 1</diffuse></material></visual>
      <visual name='rotor_4_tip_marker_visual'><pose>0.780 0.090 0.030 0 0 0</pose><geometry><box><size>0.140 0.050 0.020</size></box></geometry><material><ambient>1 1 1 1</ambient><diffuse>1 1 1 1</diffuse></material></visual>
      <gravity>1</gravity><velocity_decay /><self_collide>0</self_collide>
    </link>
    <joint name='rotor_4_joint' type='revolute'>
      <child>rotor_4</child><parent>base_link</parent>
      <axis><xyz expressed_in="__model__">0 0.13917 0.99027</xyz><limit><lower>-1e+16</lower><upper>1e+16</upper></limit><dynamics><spring_reference>0</spring_reference><spring_stiffness>0</spring_stiffness></dynamics></axis>
    </joint>

    <link name='rotor_5'>
      <pose>-4.03 1.45 0.93 0.1396263402 0 0</pose>
      <inertial><mass>2.0</mass><inertia><ixx>0.49075</ixx><ixy>0</ixy><ixz>0</ixz><iyy>0.49075</iyy><iyz>0</iyz><izz>0.98129</izz></inertia></inertial>
      <collision name='rotor_5_collision'><geometry><cylinder><length>0.025</length><radius>0.9906</radius></cylinder></geometry></collision>
      <visual name='rotor_5_visual'><geometry><cylinder><length>0.025</length><radius>0.9906</radius></cylinder></geometry><material><ambient>0.95 0.38 0.12 0.85</ambient><diffuse>0.95 0.38 0.12 0.85</diffuse></material></visual>
      <visual name='rotor_5_blades_visual'><pose>0 0 0.020 0 0 0</pose><geometry><box><size>1.650 0.070 0.014</size></box></geometry><material><ambient>0.95 0.38 0.12 1</ambient><diffuse>0.95 0.38 0.12 1</diffuse></material></visual>
      <visual name='rotor_5_tip_marker_visual'><pose>0.780 0.090 0.030 0 0 0</pose><geometry><box><size>0.140 0.050 0.020</size></box></geometry><material><ambient>1 1 1 1</ambient><diffuse>1 1 1 1</diffuse></material></visual>
      <gravity>1</gravity><velocity_decay /><self_collide>0</self_collide>
    </link>
    <joint name='rotor_5_joint' type='revolute'>
      <child>rotor_5</child><parent>base_link</parent>
      <axis><xyz expressed_in="__model__">0 -0.13917 0.99027</xyz><limit><lower>-1e+16</lower><upper>1e+16</upper></limit><dynamics><spring_reference>0</spring_reference><spring_stiffness>0</spring_stiffness></dynamics></axis>
    </joint>

    <link name='rotor_6'>
      <pose>-4.03 -1.45 0.93 -0.1396263402 0 0</pose>
      <inertial><mass>2.0</mass><inertia><ixx>0.49075</ixx><ixy>0</ixy><ixz>0</ixz><iyy>0.49075</iyy><iyz>0</iyz><izz>0.98129</izz></inertia></inertial>
      <collision name='rotor_6_collision'><geometry><cylinder><length>0.025</length><radius>0.9906</radius></cylinder></geometry></collision>
      <visual name='rotor_6_visual'><geometry><cylinder><length>0.025</length><radius>0.9906</radius></cylinder></geometry><material><ambient>0.10 0.45 0.90 0.85</ambient><diffuse>0.10 0.45 0.90 0.85</diffuse></material></visual>
      <visual name='rotor_6_blades_visual'><pose>0 0 0.020 0 0 0</pose><geometry><box><size>1.650 0.070 0.014</size></box></geometry><material><ambient>0.10 0.45 0.90 1</ambient><diffuse>0.10 0.45 0.90 1</diffuse></material></visual>
      <visual name='rotor_6_tip_marker_visual'><pose>0.780 0.090 0.030 0 0 0</pose><geometry><box><size>0.140 0.050 0.020</size></box></geometry><material><ambient>1 1 1 1</ambient><diffuse>1 1 1 1</diffuse></material></visual>
      <gravity>1</gravity><velocity_decay /><self_collide>0</self_collide>
    </link>
    <joint name='rotor_6_joint' type='revolute'>
      <child>rotor_6</child><parent>base_link</parent>
      <axis><xyz expressed_in="__model__">0 0.13917 0.99027</xyz><limit><lower>-1e+16</lower><upper>1e+16</upper></limit><dynamics><spring_reference>0</spring_reference><spring_stiffness>0</spring_stiffness></dynamics></axis>
    </joint>

    <link name='rotor_7'>
      <pose>-1.95 -1.45 0.93 0.1396263402 0 0</pose>
      <inertial><mass>2.0</mass><inertia><ixx>0.49075</ixx><ixy>0</ixy><ixz>0</ixz><iyy>0.49075</iyy><iyz>0</iyz><izz>0.98129</izz></inertia></inertial>
      <collision name='rotor_7_collision'><geometry><cylinder><length>0.025</length><radius>0.9906</radius></cylinder></geometry></collision>
      <visual name='rotor_7_visual'><geometry><cylinder><length>0.025</length><radius>0.9906</radius></cylinder></geometry><material><ambient>0.95 0.38 0.12 0.85</ambient><diffuse>0.95 0.38 0.12 0.85</diffuse></material></visual>
      <visual name='rotor_7_blades_visual'><pose>0 0 0.020 0 0 0</pose><geometry><box><size>1.650 0.070 0.014</size></box></geometry><material><ambient>0.95 0.38 0.12 1</ambient><diffuse>0.95 0.38 0.12 1</diffuse></material></visual>
      <visual name='rotor_7_tip_marker_visual'><pose>0.780 0.090 0.030 0 0 0</pose><geometry><box><size>0.140 0.050 0.020</size></box></geometry><material><ambient>1 1 1 1</ambient><diffuse>1 1 1 1</diffuse></material></visual>
      <gravity>1</gravity><velocity_decay /><self_collide>0</self_collide>
    </link>
    <joint name='rotor_7_joint' type='revolute'>
      <child>rotor_7</child><parent>base_link</parent>
      <axis><xyz expressed_in="__model__">0 -0.13917 0.99027</xyz><limit><lower>-1e+16</lower><upper>1e+16</upper></limit><dynamics><spring_reference>0</spring_reference><spring_stiffness>0</spring_stiffness></dynamics></axis>
    </joint>

    <link name='rotor_8'>
      <pose>-1.95 -4.00 0.93 -0.1396263402 0 0</pose>
      <inertial><mass>2.0</mass><inertia><ixx>0.49075</ixx><ixy>0</ixy><ixz>0</ixz><iyy>0.49075</iyy><iyz>0</iyz><izz>0.98129</izz></inertia></inertial>
      <collision name='rotor_8_collision'><geometry><cylinder><length>0.025</length><radius>0.9906</radius></cylinder></geometry></collision>
      <visual name='rotor_8_visual'><geometry><cylinder><length>0.025</length><radius>0.9906</radius></cylinder></geometry><material><ambient>0.10 0.45 0.90 0.85</ambient><diffuse>0.10 0.45 0.90 0.85</diffuse></material></visual>
      <visual name='rotor_8_blades_visual'><pose>0 0 0.020 0 0 0</pose><geometry><box><size>1.650 0.070 0.014</size></box></geometry><material><ambient>0.10 0.45 0.90 1</ambient><diffuse>0.10 0.45 0.90 1</diffuse></material></visual>
      <visual name='rotor_8_tip_marker_visual'><pose>0.780 0.090 0.030 0 0 0</pose><geometry><box><size>0.140 0.050 0.020</size></box></geometry><material><ambient>1 1 1 1</ambient><diffuse>1 1 1 1</diffuse></material></visual>
      <gravity>1</gravity><velocity_decay /><self_collide>0</self_collide>
    </link>
    <joint name='rotor_8_joint' type='revolute'>
      <child>rotor_8</child><parent>base_link</parent>
      <axis><xyz expressed_in="__model__">0 0.13917 0.99027</xyz><limit><lower>-1e+16</lower><upper>1e+16</upper></limit><dynamics><spring_reference>0</spring_reference><spring_stiffness>0</spring_stiffness></dynamics></axis>
    </joint>

    <link name='rotor_9'>
      <pose>1.95 -4.00 0.93 0.1396263402 0 0</pose>
      <inertial><mass>2.0</mass><inertia><ixx>0.49075</ixx><ixy>0</ixy><ixz>0</ixz><iyy>0.49075</iyy><iyz>0</iyz><izz>0.98129</izz></inertia></inertial>
      <collision name='rotor_9_collision'><geometry><cylinder><length>0.025</length><radius>0.9906</radius></cylinder></geometry></collision>
      <visual name='rotor_9_visual'><geometry><cylinder><length>0.025</length><radius>0.9906</radius></cylinder></geometry><material><ambient>0.10 0.45 0.90 0.85</ambient><diffuse>0.10 0.45 0.90 0.85</diffuse></material></visual>
      <visual name='rotor_9_blades_visual'><pose>0 0 0.020 0 0 0</pose><geometry><box><size>1.650 0.070 0.014</size></box></geometry><material><ambient>0.10 0.45 0.90 1</ambient><diffuse>0.10 0.45 0.90 1</diffuse></material></visual>
      <visual name='rotor_9_tip_marker_visual'><pose>0.780 0.090 0.030 0 0 0</pose><geometry><box><size>0.140 0.050 0.020</size></box></geometry><material><ambient>1 1 1 1</ambient><diffuse>1 1 1 1</diffuse></material></visual>
      <gravity>1</gravity><velocity_decay /><self_collide>0</self_collide>
    </link>
    <joint name='rotor_9_joint' type='revolute'>
      <child>rotor_9</child><parent>base_link</parent>
      <axis><xyz expressed_in="__model__">0 -0.13917 0.99027</xyz><limit><lower>-1e+16</lower><upper>1e+16</upper></limit><dynamics><spring_reference>0</spring_reference><spring_stiffness>0</spring_stiffness></dynamics></axis>
    </joint>

    <link name='rotor_10'>
      <pose>1.95 -1.45 0.93 -0.1396263402 0 0</pose>
      <inertial><mass>2.0</mass><inertia><ixx>0.49075</ixx><ixy>0</ixy><ixz>0</ixz><iyy>0.49075</iyy><iyz>0</iyz><izz>0.98129</izz></inertia></inertial>
      <collision name='rotor_10_collision'><geometry><cylinder><length>0.025</length><radius>0.9906</radius></cylinder></geometry></collision>
      <visual name='rotor_10_visual'><geometry><cylinder><length>0.025</length><radius>0.9906</radius></cylinder></geometry><material><ambient>0.95 0.38 0.12 0.85</ambient><diffuse>0.95 0.38 0.12 0.85</diffuse></material></visual>
      <visual name='rotor_10_blades_visual'><pose>0 0 0.020 0 0 0</pose><geometry><box><size>1.650 0.070 0.014</size></box></geometry><material><ambient>0.95 0.38 0.12 1</ambient><diffuse>0.95 0.38 0.12 1</diffuse></material></visual>
      <visual name='rotor_10_tip_marker_visual'><pose>0.780 0.090 0.030 0 0 0</pose><geometry><box><size>0.140 0.050 0.020</size></box></geometry><material><ambient>1 1 1 1</ambient><diffuse>1 1 1 1</diffuse></material></visual>
      <gravity>1</gravity><velocity_decay /><self_collide>0</self_collide>
    </link>
    <joint name='rotor_10_joint' type='revolute'>
      <child>rotor_10</child><parent>base_link</parent>
      <axis><xyz expressed_in="__model__">0 0.13917 0.99027</xyz><limit><lower>-1e+16</lower><upper>1e+16</upper></limit><dynamics><spring_reference>0</spring_reference><spring_stiffness>0</spring_stiffness></dynamics></axis>
    </joint>

    <link name='rotor_11'>
      <pose>4.03 -1.45 0.93 0.1396263402 0 0</pose>
      <inertial><mass>2.0</mass><inertia><ixx>0.49075</ixx><ixy>0</ixy><ixz>0</ixz><iyy>0.49075</iyy><iyz>0</iyz><izz>0.98129</izz></inertia></inertial>
      <collision name='rotor_11_collision'><geometry><cylinder><length>0.025</length><radius>0.9906</radius></cylinder></geometry></collision>
      <visual name='rotor_11_visual'><geometry><cylinder><length>0.025</length><radius>0.9906</radius></cylinder></geometry><material><ambient>0.10 0.45 0.90 0.85</ambient><diffuse>0.10 0.45 0.90 0.85</diffuse></material></visual>
      <visual name='rotor_11_blades_visual'><pose>0 0 0.020 0 0 0</pose><geometry><box><size>1.650 0.070 0.014</size></box></geometry><material><ambient>0.10 0.45 0.90 1</ambient><diffuse>0.10 0.45 0.90 1</diffuse></material></visual>
      <visual name='rotor_11_tip_marker_visual'><pose>0.780 0.090 0.030 0 0 0</pose><geometry><box><size>0.140 0.050 0.020</size></box></geometry><material><ambient>1 1 1 1</ambient><diffuse>1 1 1 1</diffuse></material></visual>
      <gravity>1</gravity><velocity_decay /><self_collide>0</self_collide>
    </link>
    <joint name='rotor_11_joint' type='revolute'>
      <child>rotor_11</child><parent>base_link</parent>
      <axis><xyz expressed_in="__model__">0 -0.13917 0.99027</xyz><limit><lower>-1e+16</lower><upper>1e+16</upper></limit><dynamics><spring_reference>0</spring_reference><spring_stiffness>0</spring_stiffness></dynamics></axis>
    </joint>

    <!-- Pusher drive fixed mass: 2x EMRAX 268 LV +100% LC motors (44.6 kg) + 2x HBCi400800 water-cooled inverters (9.6 kg). -->
    <link name='pusher_drive'>
      <pose>-1.80 0 0.25 0 0 0</pose>
      <inertial>
        <pose>0 0 0 0 0 0</pose>
        <mass>54.2</mass>
        <inertia>
          <ixx>0.460</ixx>
          <ixy>0</ixy>
          <ixz>0</ixz>
          <iyy>0.303</iyy>
          <iyz>0</iyz>
          <izz>0.317</izz>
        </inertia>
      </inertial>
    </link>
    <joint name='pusher_drive_joint' type='fixed'>
      <parent>base_link</parent>
      <child>pusher_drive</child>
    </joint>

    <link name='rotor_12'>
      <!-- Pusher thrust-direction fix: MulticopterMotorModel applies thrust along the link local +Z.
           pitch -90deg put link +Z = model -X (BACKWARD, verified -1.49 m/s^2 body_vx). pitch +90deg makes
           link +Z = model +X (FORWARD). Joint axis stays +X (spin). Was: 0 -1.5707963268 0. -->
      <pose>-1.80 0 0.25 0 1.5707963268 0</pose>
      <inertial><mass>2.22</mass><inertia><ixx>0.19769</ixx><ixy>0</ixy><ixz>0</ixz><iyy>0.19769</iyy><iyz>0</iyz><izz>0.39538</izz></inertia></inertial>
      <collision name='rotor_12_collision'><geometry><cylinder><length>0.025</length><radius>0.9</radius></cylinder></geometry></collision>
      <visual name='rotor_12_visual'><geometry><cylinder><length>0.025</length><radius>0.9</radius></cylinder></geometry><material><ambient>0.10 0.45 0.90 0.85</ambient><diffuse>0.10 0.45 0.90 0.85</diffuse></material></visual>
      <visual name='rotor_12_blades_visual'><pose>0 0 0.020 0 0 0</pose><geometry><box><size>1.500 0.080 0.014</size></box></geometry><material><ambient>0.10 0.45 0.90 1</ambient><diffuse>0.10 0.45 0.90 1</diffuse></material></visual>
      <visual name='rotor_12_tip_marker_visual'><pose>0.700 0.100 0.030 0 0 0</pose><geometry><box><size>0.140 0.055 0.020</size></box></geometry><material><ambient>1 1 1 1</ambient><diffuse>1 1 1 1</diffuse></material></visual>
      <gravity>1</gravity><velocity_decay /><self_collide>0</self_collide>
    </link>
    <joint name='rotor_12_joint' type='revolute'>
      <child>rotor_12</child><parent>base_link</parent>
      <axis><xyz expressed_in="__model__">1 0 0</xyz><limit><lower>-1e+16</lower><upper>1e+16</upper></limit><dynamics><spring_reference>0</spring_reference><spring_stiffness>0</spring_stiffness></dynamics></axis>
    </joint>

    <link name='left_aileron'>
      <pose relative_to='base_link'>-0.6825 3.280 0.730 0 0 0</pose>
      <inertial><mass>0.001</mass><inertia><ixx>0.00001</ixx><ixy>0</ixy><ixz>0</ixz><iyy>0.00001</iyy><iyz>0</iyz><izz>0.00001</izz></inertia></inertial>
      <collision name='left_aileron_collision'><geometry><box><size>0.405 0.640 0.040</size></box></geometry></collision>
      <visual name='left_aileron_visual'><geometry><box><size>0.405 0.640 0.040</size></box></geometry><material><ambient>0.65 0.68 0.70 1</ambient><diffuse>0.65 0.68 0.70 1</diffuse></material></visual>
    </link>
    <link name='right_aileron'>
      <pose relative_to='base_link'>-0.6825 -3.280 0.730 0 0 0</pose>
      <inertial><mass>0.001</mass><inertia><ixx>0.00001</ixx><ixy>0</ixy><ixz>0</ixz><iyy>0.00001</iyy><iyz>0</iyz><izz>0.00001</izz></inertia></inertial>
      <collision name='right_aileron_collision'><geometry><box><size>0.405 0.640 0.040</size></box></geometry></collision>
      <visual name='right_aileron_visual'><geometry><box><size>0.405 0.640 0.040</size></box></geometry><material><ambient>0.65 0.68 0.70 1</ambient><diffuse>0.65 0.68 0.70 1</diffuse></material></visual>
    </link>
    <link name='elevator'>
      <pose relative_to='base_link'>-5.379 0 0.760 0 0 0</pose>
      <inertial><mass>0.001</mass><inertia><ixx>0.00001</ixx><ixy>0</ixy><ixz>0</ixz><iyy>0.00001</iyy><iyz>0</iyz><izz>0.00001</izz></inertia></inertial>
      <collision name='elevator_collision'><geometry><box><size>0.242 2.000 0.040</size></box></geometry></collision>
      <visual name='elevator_visual'><geometry><box><size>0.242 2.000 0.040</size></box></geometry><material><ambient>0.65 0.68 0.70 1</ambient><diffuse>0.65 0.68 0.70 1</diffuse></material></visual>
    </link>
    <link name='right_rudder'>
      <pose relative_to='base_link'>-5.742 1.45 0.358 0 0 0</pose>
      <inertial><mass>0.001</mass><inertia><ixx>0.00001</ixx><ixy>0</ixy><ixz>0</ixz><iyy>0.00001</iyy><iyz>0</iyz><izz>0.00001</izz></inertia></inertial>
      <collision name='right_rudder_collision'><geometry><box><size>0.243 0.040 0.700</size></box></geometry></collision>
      <visual name='right_rudder_visual'><geometry><box><size>0.243 0.040 0.700</size></box></geometry><material><ambient>0.65 0.68 0.70 1</ambient><diffuse>0.65 0.68 0.70 1</diffuse></material></visual>
    </link>
    <link name='left_rudder'>
      <pose relative_to='base_link'>-5.742 -1.45 0.358 0 0 0</pose>
      <inertial><mass>0.001</mass><inertia><ixx>0.00001</ixx><ixy>0</ixy><ixz>0</ixz><iyy>0.00001</iyy><iyz>0</iyz><izz>0.00001</izz></inertia></inertial>
      <collision name='left_rudder_collision'><geometry><box><size>0.243 0.040 0.700</size></box></geometry></collision>
      <visual name='left_rudder_visual'><geometry><box><size>0.243 0.040 0.700</size></box></geometry><material><ambient>0.65 0.68 0.70 1</ambient><diffuse>0.65 0.68 0.70 1</diffuse></material></visual>
    </link>
    <link name='left_flap'>
      <pose relative_to='base_link'>-0.6825 1.650 0.730 0 0 0</pose>
      <inertial><mass>0.001</mass><inertia><ixx>0.00001</ixx><ixy>0</ixy><ixz>0</ixz><iyy>0.00001</iyy><iyz>0</iyz><izz>0.00001</izz></inertia></inertial>
      <collision name='left_flap_collision'><geometry><box><size>0.405 2.000 0.040</size></box></geometry></collision>
      <visual name='left_flap_visual'><geometry><box><size>0.405 2.000 0.040</size></box></geometry><material><ambient>0.90 0.55 0.20 1</ambient><diffuse>0.90 0.55 0.20 1</diffuse></material></visual>
    </link>
    <link name='right_flap'>
      <pose relative_to='base_link'>-0.6825 -1.650 0.730 0 0 0</pose>
      <inertial><mass>0.001</mass><inertia><ixx>0.00001</ixx><ixy>0</ixy><ixz>0</ixz><iyy>0.00001</iyy><iyz>0</iyz><izz>0.00001</izz></inertia></inertial>
      <collision name='right_flap_collision'><geometry><box><size>0.405 2.000 0.040</size></box></geometry></collision>
      <visual name='right_flap_visual'><geometry><box><size>0.405 2.000 0.040</size></box></geometry><material><ambient>0.90 0.55 0.20 1</ambient><diffuse>0.90 0.55 0.20 1</diffuse></material></visual>
    </link>

    <joint name='servo_0' type='revolute'>
      <parent>base_link</parent><child>left_aileron</child>
      <pose relative_to='base_link'>-0.585 3.280 0.730 0 0 0</pose>
      <axis><xyz>0 1 0</xyz><limit><lower>-0.78</lower><upper>0.78</upper></limit><dynamics><damping>1.0</damping></dynamics></axis>
      <physics><ode><implicit_spring_damper>1</implicit_spring_damper></ode></physics>
    </joint>
    <joint name='servo_1' type='revolute'>
      <parent>base_link</parent><child>right_aileron</child>
      <pose relative_to='base_link'>-0.585 -3.280 0.730 0 0 0</pose>
      <axis><xyz>0 1 0</xyz><limit><lower>-0.78</lower><upper>0.78</upper></limit><dynamics><damping>1.0</damping></dynamics></axis>
      <physics><ode><implicit_spring_damper>1</implicit_spring_damper></ode></physics>
    </joint>
    <joint name='servo_2' type='revolute'>
      <parent>base_link</parent><child>elevator</child>
      <pose relative_to='base_link'>-5.321 0 0.760 0 0 0</pose>
      <axis><xyz>0 1 0</xyz><limit><lower>-0.78</lower><upper>0.78</upper></limit><dynamics><damping>1.0</damping></dynamics></axis>
      <physics><ode><implicit_spring_damper>1</implicit_spring_damper></ode></physics>
    </joint>
    <joint name='servo_3' type='revolute'>
      <parent>base_link</parent><child>right_rudder</child>
      <pose relative_to='base_link'>-5.683 1.45 0.358 0 0 0</pose>
      <axis><xyz>0 0 1</xyz><limit><lower>-0.78</lower><upper>0.78</upper></limit><dynamics><damping>1.0</damping></dynamics></axis>
      <physics><ode><implicit_spring_damper>1</implicit_spring_damper></ode></physics>
    </joint>
    <joint name='servo_4' type='revolute'>
      <parent>base_link</parent><child>left_rudder</child>
      <pose relative_to='base_link'>-5.683 -1.45 0.358 0 0 0</pose>
      <axis><xyz>0 0 1</xyz><limit><lower>-0.78</lower><upper>0.78</upper></limit><dynamics><damping>1.0</damping></dynamics></axis>
      <physics><ode><implicit_spring_damper>1</implicit_spring_damper></ode></physics>
    </joint>
    <joint name='servo_5' type='revolute'>
      <parent>base_link</parent><child>left_flap</child>
      <pose relative_to='base_link'>-0.585 1.650 0.730 0 0 0</pose>
      <axis><xyz>0 1 0</xyz><limit><lower>-0.785</lower><upper>0.785</upper></limit><dynamics><damping>1.0</damping></dynamics></axis>
      <physics><ode><implicit_spring_damper>1</implicit_spring_damper></ode></physics>
    </joint>
    <joint name='servo_6' type='revolute'>
      <parent>base_link</parent><child>right_flap</child>
      <pose relative_to='base_link'>-0.585 -1.650 0.730 0 0 0</pose>
      <axis><xyz>0 1 0</xyz><limit><lower>-0.785</lower><upper>0.785</upper></limit><dynamics><damping>1.0</damping></dynamics></axis>
      <physics><ode><implicit_spring_damper>1</implicit_spring_damper></ode></physics>
    </joint>

    <!-- Fixed lifting surfaces (real planform, mass~=0; aero stays lumped AdvancedLiftDrag). -->
    <link name='wing_fixed'>
      <pose relative_to='base_link'>-0.135 0 0.930 0 0 0</pose>
      <inertial><mass>0.001</mass><inertia><ixx>1e-5</ixx><ixy>0</ixy><ixz>0</ixz><iyy>1e-5</iyy><iyz>0</iyz><izz>1e-5</izz></inertia></inertial>
      <visual name='wing_fixed_visual'><geometry><box><size>1.500 8.000 0.255</size></box></geometry><material><ambient>0.55 0.62 0.72 1</ambient><diffuse>0.55 0.62 0.72 1</diffuse></material></visual>
    </link>
    <joint name='wing_fixed_joint' type='fixed'><parent>base_link</parent><child>wing_fixed</child></joint>
    <link name='htail_fixed'>
      <pose relative_to='base_link'>-4.896 0 0.960 0 0 0</pose>
      <inertial><mass>0.001</mass><inertia><ixx>1e-5</ixx><ixy>0</ixy><ixz>0</ixz><iyy>1e-5</iyy><iyz>0</iyz><izz>1e-5</izz></inertia></inertial>
      <visual name='htail_fixed_visual'><geometry><box><size>0.601 2.900 0.110</size></box></geometry><material><ambient>0.50 0.66 0.58 1</ambient><diffuse>0.50 0.66 0.58 1</diffuse></material></visual>
    </link>
    <joint name='htail_fixed_joint' type='fixed'><parent>base_link</parent><child>htail_fixed</child></joint>
    <link name='vtail_r_fixed'>
      <pose relative_to='base_link'>-5.382 1.45 0.358 0 0 0</pose>
      <inertial><mass>0.001</mass><inertia><ixx>1e-5</ixx><ixy>0</ixy><ixz>0</ixz><iyy>1e-5</iyy><iyz>0</iyz><izz>1e-5</izz></inertia></inertial>
      <visual name='vtail_r_fixed_visual'><geometry><box><size>0.477 0.086 0.700</size></box></geometry><material><ambient>0.72 0.58 0.42 1</ambient><diffuse>0.72 0.58 0.42 1</diffuse></material></visual>
    </link>
    <joint name='vtail_r_fixed_joint' type='fixed'><parent>base_link</parent><child>vtail_r_fixed</child></joint>
    <link name='vtail_l_fixed'>
      <pose relative_to='base_link'>-5.382 -1.45 0.358 0 0 0</pose>
      <inertial><mass>0.001</mass><inertia><ixx>1e-5</ixx><ixy>0</ixy><ixz>0</ixz><iyy>1e-5</iyy><iyz>0</iyz><izz>1e-5</izz></inertia></inertial>
      <visual name='vtail_l_fixed_visual'><geometry><box><size>0.477 0.086 0.700</size></box></geometry><material><ambient>0.72 0.58 0.42 1</ambient><diffuse>0.72 0.58 0.42 1</diffuse></material></visual>
    </link>
    <joint name='vtail_l_fixed_joint' type='fixed'><parent>base_link</parent><child>vtail_l_fixed</child></joint>

    <plugin filename="libAirSpeedPlugin.so" name="px4::AirSpeed">
      <link_name>base_link</link_name>
    </plugin>

    <plugin filename="gz-sim-advanced-lift-drag-system" name="gz::sim::systems::AdvancedLiftDrag">
      <a0>0.0</a0>
      <CL0>-0.0020946</CL0>
      <AR>5.3333333</AR>
      <eff>0.85</eff>
      <CLa>4.7441590</CLa>
      <CD0>0.0064776</CD0>
      <Cem0>0.0038936</Cem0>
      <Cema>-0.5043557</Cema>
      <CYb>-0.0861307</CYb>
      <Cellb>-0.0150000</Cellb>
      <Cenb>0.0604482</Cenb>
      <CDp>0.0005695</CDp>
      <CYp>-0.0343598</CYp>
      <CLp>-0.0495136</CLp>
      <Cellp>-0.4800257</Cellp>
      <Cemp>0.1414532</Cemp>
      <Cenp>0.0237823</Cenp>
      <CDq>-0.0154674</CDq>
      <CYq>0.0044313</CYq>
      <CLq>7.8249252</CLq>
      <Cellq>-0.0003302</Cellq>
      <Cemq>-15.8709170</Cemq>
      <Cenq>0.0063892</Cenq>
      <CDr>0.0007566</CDr>
      <CYr>0.1323770</CYr>
      <CLr>0.0006863</CLr>
      <Cellr>0.0047377</Cellr>
      <Cemr>-0.0035497</Cemr>
      <Cenr>-0.0883947</Cenr>
      <alpha_stall>0.3391428111</alpha_stall>
      <CLa_stall>-3.85</CLa_stall>
      <CDa_stall>-0.9233984055</CDa_stall>
      <Cema_stall>0</Cema_stall>
      <cp>0 0 0</cp>
      <area>12.0</area>
      <mac>1.5</mac>
      <air_density>1.2041</air_density>
      <forward>1 0 0</forward>
      <upward>0 0 1</upward>
      <link_name>base_link</link_name>
      <num_ctrl_surfaces>0</num_ctrl_surfaces>
    </plugin>

    <plugin filename="gz-sim-lift-drag-system" name="gz::sim::systems::LiftDrag">
      <a0>0.05</a0><cla>0.0</cla><cda>0.0</cda><cma>0</cma><alpha_stall>0.34</alpha_stall><cla_stall>0.0</cla_stall><cda_stall>0.0</cda_stall><cma_stall>0</cma_stall>
      <cp>-0.585 3.280 0.730</cp><area>0.330</area><air_density>1.2041</air_density><forward>1 0 0</forward><upward>0 0 1</upward><link_name>base_link</link_name><control_joint_name>servo_0</control_joint_name><control_joint_rad_to_cl>-1.05</control_joint_rad_to_cl>
    </plugin>
    <plugin filename="gz-sim-lift-drag-system" name="gz::sim::systems::LiftDrag">
      <a0>0.05</a0><cla>0.0</cla><cda>0.0</cda><cma>0</cma><alpha_stall>0.34</alpha_stall><cla_stall>0.0</cla_stall><cda_stall>0.0</cda_stall><cma_stall>0</cma_stall>
      <cp>-0.585 -3.280 0.730</cp><area>0.330</area><air_density>1.2041</air_density><forward>1 0 0</forward><upward>0 0 1</upward><link_name>base_link</link_name><control_joint_name>servo_1</control_joint_name><control_joint_rad_to_cl>-1.05</control_joint_rad_to_cl>
    </plugin>
    <plugin filename="gz-sim-lift-drag-system" name="gz::sim::systems::LiftDrag">
      <a0>-0.2</a0><cla>0.0</cla><cda>0.0</cda><cma>0</cma><alpha_stall>0.34</alpha_stall><cla_stall>0.0</cla_stall><cda_stall>0.0</cda_stall><cma_stall>0</cma_stall>
      <cp>-5.321 0 0.760</cp><area>1.81</area><air_density>1.2041</air_density><forward>1 0 0</forward><upward>0 0 1</upward><link_name>base_link</link_name><control_joint_name>servo_2</control_joint_name><control_joint_rad_to_cl>-2.67</control_joint_rad_to_cl>
    </plugin>
    <plugin filename="gz-sim-lift-drag-system" name="gz::sim::systems::LiftDrag">
      <a0>0.0</a0><cla>0.0</cla><cda>0.0</cda><cma>0</cma><alpha_stall>0.34</alpha_stall><cla_stall>0.0</cla_stall><cda_stall>0.0</cda_stall><cma_stall>0</cma_stall>
      <cp>-5.683 1.45 0.358</cp><area>0.504</area><air_density>1.2041</air_density><forward>1 0 0</forward><upward>0 1 0</upward><link_name>base_link</link_name><control_joint_name>servo_3</control_joint_name><control_joint_rad_to_cl>1.41</control_joint_rad_to_cl>
    </plugin>
    <plugin filename="gz-sim-lift-drag-system" name="gz::sim::systems::LiftDrag">
      <a0>0.0</a0><cla>0.0</cla><cda>0.0</cda><cma>0</cma><alpha_stall>0.34</alpha_stall><cla_stall>0.0</cla_stall><cda_stall>0.0</cda_stall><cma_stall>0</cma_stall>
      <cp>-5.683 -1.45 0.358</cp><area>0.504</area><air_density>1.2041</air_density><forward>1 0 0</forward><upward>0 1 0</upward><link_name>base_link</link_name><control_joint_name>servo_4</control_joint_name><control_joint_rad_to_cl>1.41</control_joint_rad_to_cl>
    </plugin>
    <plugin filename="gz-sim-lift-drag-system" name="gz::sim::systems::LiftDrag">
      <a0>0.05</a0><cla>0.0</cla><cda>0.0</cda><cma>0</cma><alpha_stall>0.34</alpha_stall><cla_stall>0.0</cla_stall><cda_stall>0.0</cda_stall><cma_stall>0</cma_stall>
      <cp>-0.585 1.650 0.730</cp><area>3.00</area><air_density>1.2041</air_density><forward>1 0 0</forward><upward>0 0 1</upward><link_name>base_link</link_name><control_joint_name>servo_5</control_joint_name><control_joint_rad_to_cl>1.4</control_joint_rad_to_cl>
    </plugin>
    <plugin filename="gz-sim-lift-drag-system" name="gz::sim::systems::LiftDrag">
      <a0>0.05</a0><cla>0.0</cla><cda>0.0</cda><cma>0</cma><alpha_stall>0.34</alpha_stall><cla_stall>0.0</cla_stall><cda_stall>0.0</cda_stall><cma_stall>0</cma_stall>
      <cp>-0.585 -1.650 0.730</cp><area>3.00</area><air_density>1.2041</air_density><forward>1 0 0</forward><upward>0 0 1</upward><link_name>base_link</link_name><control_joint_name>servo_6</control_joint_name><control_joint_rad_to_cl>1.4</control_joint_rad_to_cl>
    </plugin>

    <!-- [MOD-4] Flaperon/spoiler DRAG term (custom). ADDS drag only; existing CL coefficients unchanged.
         dCdS = cd_plate * flap_area * sin(|delta|) per flaperon (servo_5,servo_6), summed; applied at CoM
         (symmetric up-deflection = pure drag, no roll). User-authorised drag-term addition. -->
    <plugin filename="FlaperonDrag" name="FlaperonDrag">
      <link_name>base_link</link_name>
      <air_density>1.2041</air_density>
      <cd_plate>1.0</cd_plate>
      <flap_area>0.81</flap_area>
      <baseline_rad>0.61</baseline_rad>
    </plugin>

    <plugin filename="gz-sim-joint-position-controller-system" name="gz::sim::systems::JointPositionController"><joint_name>servo_0</joint_name><sub_topic>servo_0</sub_topic><p_gain>10</p_gain><i_gain>0</i_gain><d_gain>0</d_gain></plugin>
    <plugin filename="gz-sim-joint-position-controller-system" name="gz::sim::systems::JointPositionController"><joint_name>servo_1</joint_name><sub_topic>servo_1</sub_topic><p_gain>10</p_gain><i_gain>0</i_gain><d_gain>0</d_gain></plugin>
    <plugin filename="gz-sim-joint-position-controller-system" name="gz::sim::systems::JointPositionController"><joint_name>servo_2</joint_name><sub_topic>servo_2</sub_topic><p_gain>10</p_gain><i_gain>0</i_gain><d_gain>0</d_gain></plugin>
    <plugin filename="gz-sim-joint-position-controller-system" name="gz::sim::systems::JointPositionController"><joint_name>servo_3</joint_name><sub_topic>servo_3</sub_topic><p_gain>10</p_gain><i_gain>0</i_gain><d_gain>0</d_gain></plugin>
    <plugin filename="gz-sim-joint-position-controller-system" name="gz::sim::systems::JointPositionController"><joint_name>servo_4</joint_name><sub_topic>servo_4</sub_topic><p_gain>10</p_gain><i_gain>0</i_gain><d_gain>0</d_gain></plugin>
    <plugin filename="gz-sim-joint-position-controller-system" name="gz::sim::systems::JointPositionController"><joint_name>servo_5</joint_name><sub_topic>servo_5</sub_topic><p_gain>10</p_gain><i_gain>0</i_gain><d_gain>0</d_gain></plugin>
    <plugin filename="gz-sim-joint-position-controller-system" name="gz::sim::systems::JointPositionController"><joint_name>servo_6</joint_name><sub_topic>servo_6</sub_topic><p_gain>10</p_gain><i_gain>0</i_gain><d_gain>0</d_gain></plugin>

    <plugin filename="gz-sim-multicopter-motor-model-system" name="gz::sim::systems::MulticopterMotorModel"><jointName>rotor_0_joint</jointName><linkName>rotor_0</linkName><turningDirection>cw</turningDirection><timeConstantUp>0.17</timeConstantUp><timeConstantDown>0.18</timeConstantDown><maxRotVelocity>249.23</maxRotVelocity><motorConstant>0.0371333</motorConstant><momentConstant>0.0878447</momentConstant><commandSubTopic>command/motor_speed</commandSubTopic><motorNumber>0</motorNumber><rotorDragCoefficient>8.06428e-05</rotorDragCoefficient><rollingMomentCoefficient>1e-06</rollingMomentCoefficient><rotorVelocitySlowdownSim>10</rotorVelocitySlowdownSim><motorType>velocity</motorType></plugin>
    <plugin filename="gz-sim-multicopter-motor-model-system" name="gz::sim::systems::MulticopterMotorModel"><jointName>rotor_1_joint</jointName><linkName>rotor_1</linkName><turningDirection>ccw</turningDirection><timeConstantUp>0.17</timeConstantUp><timeConstantDown>0.18</timeConstantDown><maxRotVelocity>249.23</maxRotVelocity><motorConstant>0.0371333</motorConstant><momentConstant>0.0878447</momentConstant><commandSubTopic>command/motor_speed</commandSubTopic><motorNumber>1</motorNumber><rotorDragCoefficient>8.06428e-05</rotorDragCoefficient><rollingMomentCoefficient>1e-06</rollingMomentCoefficient><rotorVelocitySlowdownSim>10</rotorVelocitySlowdownSim><motorType>velocity</motorType></plugin>
    <plugin filename="gz-sim-multicopter-motor-model-system" name="gz::sim::systems::MulticopterMotorModel"><jointName>rotor_2_joint</jointName><linkName>rotor_2</linkName><turningDirection>cw</turningDirection><timeConstantUp>0.17</timeConstantUp><timeConstantDown>0.18</timeConstantDown><maxRotVelocity>249.23</maxRotVelocity><motorConstant>0.0371333</motorConstant><momentConstant>0.0878447</momentConstant><commandSubTopic>command/motor_speed</commandSubTopic><motorNumber>2</motorNumber><rotorDragCoefficient>8.06428e-05</rotorDragCoefficient><rollingMomentCoefficient>1e-06</rollingMomentCoefficient><rotorVelocitySlowdownSim>10</rotorVelocitySlowdownSim><motorType>velocity</motorType></plugin>
    <plugin filename="gz-sim-multicopter-motor-model-system" name="gz::sim::systems::MulticopterMotorModel"><jointName>rotor_3_joint</jointName><linkName>rotor_3</linkName><turningDirection>cw</turningDirection><timeConstantUp>0.17</timeConstantUp><timeConstantDown>0.18</timeConstantDown><maxRotVelocity>249.23</maxRotVelocity><motorConstant>0.0371333</motorConstant><momentConstant>0.0878447</momentConstant><commandSubTopic>command/motor_speed</commandSubTopic><motorNumber>3</motorNumber><rotorDragCoefficient>8.06428e-05</rotorDragCoefficient><rollingMomentCoefficient>1e-06</rollingMomentCoefficient><rotorVelocitySlowdownSim>10</rotorVelocitySlowdownSim><motorType>velocity</motorType></plugin>
    <plugin filename="gz-sim-multicopter-motor-model-system" name="gz::sim::systems::MulticopterMotorModel"><jointName>rotor_4_joint</jointName><linkName>rotor_4</linkName><turningDirection>ccw</turningDirection><timeConstantUp>0.17</timeConstantUp><timeConstantDown>0.18</timeConstantDown><maxRotVelocity>249.23</maxRotVelocity><motorConstant>0.0371333</motorConstant><momentConstant>0.0878447</momentConstant><commandSubTopic>command/motor_speed</commandSubTopic><motorNumber>4</motorNumber><rotorDragCoefficient>8.06428e-05</rotorDragCoefficient><rollingMomentCoefficient>1e-06</rollingMomentCoefficient><rotorVelocitySlowdownSim>10</rotorVelocitySlowdownSim><motorType>velocity</motorType></plugin>
    <plugin filename="gz-sim-multicopter-motor-model-system" name="gz::sim::systems::MulticopterMotorModel"><jointName>rotor_5_joint</jointName><linkName>rotor_5</linkName><turningDirection>cw</turningDirection><timeConstantUp>0.17</timeConstantUp><timeConstantDown>0.18</timeConstantDown><maxRotVelocity>249.23</maxRotVelocity><motorConstant>0.0371333</motorConstant><momentConstant>0.0878447</momentConstant><commandSubTopic>command/motor_speed</commandSubTopic><motorNumber>5</motorNumber><rotorDragCoefficient>8.06428e-05</rotorDragCoefficient><rollingMomentCoefficient>1e-06</rollingMomentCoefficient><rotorVelocitySlowdownSim>10</rotorVelocitySlowdownSim><motorType>velocity</motorType></plugin>
    <plugin filename="gz-sim-multicopter-motor-model-system" name="gz::sim::systems::MulticopterMotorModel"><jointName>rotor_6_joint</jointName><linkName>rotor_6</linkName><turningDirection>ccw</turningDirection><timeConstantUp>0.17</timeConstantUp><timeConstantDown>0.18</timeConstantDown><maxRotVelocity>249.23</maxRotVelocity><motorConstant>0.0371333</motorConstant><momentConstant>0.0878447</momentConstant><commandSubTopic>command/motor_speed</commandSubTopic><motorNumber>6</motorNumber><rotorDragCoefficient>8.06428e-05</rotorDragCoefficient><rollingMomentCoefficient>1e-06</rollingMomentCoefficient><rotorVelocitySlowdownSim>10</rotorVelocitySlowdownSim><motorType>velocity</motorType></plugin>
    <plugin filename="gz-sim-multicopter-motor-model-system" name="gz::sim::systems::MulticopterMotorModel"><jointName>rotor_7_joint</jointName><linkName>rotor_7</linkName><turningDirection>cw</turningDirection><timeConstantUp>0.17</timeConstantUp><timeConstantDown>0.18</timeConstantDown><maxRotVelocity>249.23</maxRotVelocity><motorConstant>0.0371333</motorConstant><momentConstant>0.0878447</momentConstant><commandSubTopic>command/motor_speed</commandSubTopic><motorNumber>7</motorNumber><rotorDragCoefficient>8.06428e-05</rotorDragCoefficient><rollingMomentCoefficient>1e-06</rollingMomentCoefficient><rotorVelocitySlowdownSim>10</rotorVelocitySlowdownSim><motorType>velocity</motorType></plugin>
    <plugin filename="gz-sim-multicopter-motor-model-system" name="gz::sim::systems::MulticopterMotorModel"><jointName>rotor_8_joint</jointName><linkName>rotor_8</linkName><turningDirection>ccw</turningDirection><timeConstantUp>0.17</timeConstantUp><timeConstantDown>0.18</timeConstantDown><maxRotVelocity>249.23</maxRotVelocity><motorConstant>0.0371333</motorConstant><momentConstant>0.0878447</momentConstant><commandSubTopic>command/motor_speed</commandSubTopic><motorNumber>8</motorNumber><rotorDragCoefficient>8.06428e-05</rotorDragCoefficient><rollingMomentCoefficient>1e-06</rollingMomentCoefficient><rotorVelocitySlowdownSim>10</rotorVelocitySlowdownSim><motorType>velocity</motorType></plugin>
    <plugin filename="gz-sim-multicopter-motor-model-system" name="gz::sim::systems::MulticopterMotorModel"><jointName>rotor_9_joint</jointName><linkName>rotor_9</linkName><turningDirection>ccw</turningDirection><timeConstantUp>0.17</timeConstantUp><timeConstantDown>0.18</timeConstantDown><maxRotVelocity>249.23</maxRotVelocity><motorConstant>0.0371333</motorConstant><momentConstant>0.0878447</momentConstant><commandSubTopic>command/motor_speed</commandSubTopic><motorNumber>9</motorNumber><rotorDragCoefficient>8.06428e-05</rotorDragCoefficient><rollingMomentCoefficient>1e-06</rollingMomentCoefficient><rotorVelocitySlowdownSim>10</rotorVelocitySlowdownSim><motorType>velocity</motorType></plugin>
    <plugin filename="gz-sim-multicopter-motor-model-system" name="gz::sim::systems::MulticopterMotorModel"><jointName>rotor_10_joint</jointName><linkName>rotor_10</linkName><turningDirection>cw</turningDirection><timeConstantUp>0.17</timeConstantUp><timeConstantDown>0.18</timeConstantDown><maxRotVelocity>249.23</maxRotVelocity><motorConstant>0.0371333</motorConstant><momentConstant>0.0878447</momentConstant><commandSubTopic>command/motor_speed</commandSubTopic><motorNumber>10</motorNumber><rotorDragCoefficient>8.06428e-05</rotorDragCoefficient><rollingMomentCoefficient>1e-06</rollingMomentCoefficient><rotorVelocitySlowdownSim>10</rotorVelocitySlowdownSim><motorType>velocity</motorType></plugin>
    <plugin filename="gz-sim-multicopter-motor-model-system" name="gz::sim::systems::MulticopterMotorModel"><jointName>rotor_11_joint</jointName><linkName>rotor_11</linkName><turningDirection>ccw</turningDirection><timeConstantUp>0.17</timeConstantUp><timeConstantDown>0.18</timeConstantDown><maxRotVelocity>249.23</maxRotVelocity><motorConstant>0.0371333</motorConstant><momentConstant>0.0878447</momentConstant><commandSubTopic>command/motor_speed</commandSubTopic><motorNumber>11</motorNumber><rotorDragCoefficient>8.06428e-05</rotorDragCoefficient><rollingMomentCoefficient>1e-06</rollingMomentCoefficient><rotorVelocitySlowdownSim>10</rotorVelocitySlowdownSim><motorType>velocity</motorType></plugin>
    <plugin filename="gz-sim-multicopter-motor-model-system" name="gz::sim::systems::MulticopterMotorModel"><jointName>rotor_12_joint</jointName><linkName>rotor_12</linkName><turningDirection>ccw</turningDirection><timeConstantUp>0.22</timeConstantUp><timeConstantDown>0.30</timeConstantDown><maxRotVelocity>251.327</maxRotVelocity><motorConstant>0.0443472</motorConstant><momentConstant>0.169572</momentConstant><commandSubTopic>command/motor_speed</commandSubTopic><motorNumber>12</motorNumber><rotorDragCoefficient>8.06428e-05</rotorDragCoefficient><rollingMomentCoefficient>1e-06</rollingMomentCoefficient><rotorVelocitySlowdownSim>10</rotorVelocitySlowdownSim><motorType>velocity</motorType></plugin>
  </model>
</sdf>
